Workbook
Name BefFastighetsskötsel: '2. Kalkyldata'!$G$34
Name BefMedia: '2. Kalkyldata'!$G$37
Name BefPlaneratunderhåll: '2. Kalkyldata'!$G$36
Name BefReparationer: '2. Kalkyldata'!$G$35
Name BefÖvrigaförvaltningskostnader: '2. Kalkyldata'!$G$38
Name FemtonÅrFastighetsskötsel: '2. Kalkyldata'!$M$34
Name FemtonÅrMedia: '2. Kalkyldata'!$M$37
Name FemtonÅrPlaneratUnderhåll: '2. Kalkyldata'!$M$36
Name FemtonÅrReparationer: '2. Kalkyldata'!$M$35
Name FemtonÅrÖvrigaFörvaltningskostnader: '2. Kalkyldata'!$M$38
Name Höjnin1: '2. Kalkyldata'!$L$33
Name Höjning2: '2. Kalkyldata'!$M$33
Name Inflation: '2. Kalkyldata'!$M$9
Name NybFastighetsskötsel: '2. Kalkyldata'!$H$34
Name NybMedia: '2. Kalkyldata'!$H$37
Name NybPlaneratunderhåll: '2. Kalkyldata'!$H$36
Name NybReparationer: '2. Kalkyldata'!$H$35
Name NybÖvrigaförvaltningskostnader: '2. Kalkyldata'!$H$38
Name TioÅrFastighetsskötsel: '2. Kalkyldata'!$L$34
Name TioÅrMedia: '2. Kalkyldata'!$L$37
Name TioÅrPlaneratUnderhåll: '2. Kalkyldata'!$L$36
Name TioÅrReparationer: '2. Kalkyldata'!$L$35
Name TioÅrÖvrigaFörvaltningskostnader: '2. Kalkyldata'!$L$38

Sheet 1. Framskrivningsunderlag
J1: 1. Gamla Hjälptabeller Tryck på + -tecknen för att visa
B2: Investeringskalkyl, framskrivningsunderlag | R2: 2. Uppdateringshistorik Tryck på + -tecknen för att visa
B3: Projektnamn
B4: Kalkyl utförd av: | G4: Fyll i
B5: Fastighet: | G5: Fyll i | S5: Utförd av
B6: Objekt: | G6: Fyll i | K6: ='2. Kalkyldata'!$G$6 -> Fyll i | R6: 1. Möjliggjort redigering i fält som måste fyllas i - utan att ta bort bladets skydd
B7: Projektnummer: | G7: Fyll i | R7: 3. Avsevärt förenklat ifyllnaden i första bladet | S7: JW
B8: Fastighetsarea (markareal): | G8: Fyll i | K8: ='2. Kalkyldata'!$J$6 -> Fyll i | R8: 4. Flik 2: Lagt till indikation om vilka fält som är tvingande | S8: JW
B9: Area (BRA): | G9: Fyll i | K9: ='2. Kalkyldata'!$I$6 -> Fyll i | R9: 5. Flik 2: Lagt till notifikationer om t.ex. driftkostnader ej är angivna, eller om kalkylperiod inte matchar med avtalsperiod mm | S9: JW
B10: Area (BTA): | G10: Fyll i | R10: 6. Flik 4: Justerat så att indexpåslag på hyran endast utgår från året efter avtalet börjar gälla. Förut beräknades indexpåslag från Kalkylstart, även om avtalet började gälla i framtiden. På detta vis kan vi lättare lägga in "etappvisa" tillträden till lokaler utan att det blir stökigt i utfallet för hyran. | S10: JW
B11: Typ av projekt: | G11: Fyll i
B12: Momsregistreringsgrad före: | G12: Fyll i
B13: Momsregistreringsgrad efter: | G13: Fyll i | R13: 7. Lagt till indexuppräkning på "Central administration" | S13: JW
B15: Projektbeskrivning | K15: kvm | L15: BRA/plats | M15: Inv belopp | N15: kr/kvm | O15: Inv belopp per plats | P15: Antal platser | R15: 8. Lagt till indikation på flik 2. om eget antagande om restvärde fyllts i på flik 5. IRR. | S15: JW
B16: Åtgärder | E16: kvm (BRA) | F16: Investering | G16: kr/kvm | R16: 9. Tagit bort funktionen som uppräknar projektbudgeten med avseende på inflation om den sker i framtiden. Detta får vi själva ta hänsyn till när vi upprättar projektbudgeten. | S16: JW
B17: ='Kontoplan RR'!E6 -> Befintligt | E17: =SUMIF('2. Kalkyldata'!$E$23:$E$27,LEFT('1. Framskrivningsunderlag'!$B17,3),'2. Kalkyldata'!$H$23:$H$28) -> 0 | F17: =SUMIF('2. Kalkyldata'!$E$23:$E$27,LEFT('1. Framskrivningsunderlag'!$B17,3),'2. Kalkyldata'!$W$23:$W$28) -> 0 | G17: =IFERROR($M17/E17,0) -> 0 | K17: =SUMIF('2. Kalkyldata'!$E$23:$E$27,LEFT('1. Framskrivningsunderlag'!$B17,3),'2. Kalkyldata'!$H$23:$H$28) -> 0 | L17: =IFERROR($K17/$P17,0) -> 0 | M17: =SUMIF('2. Kalkyldata'!$E$23:$E$27,LEFT('1. Framskrivningsunderlag'!$B17,3),'2. Kalkyldata'!$W$23:$W$28) -> 0 | N17: =IFERROR($M17/$K17,0) -> 0 | O17: =IFERROR($E17/$P17,0) -> 0 | P17: =SUMIF('2. Kalkyldata'!$E$23:$E$27,LEFT('1. Framskrivningsunderlag'!$B17,3),'2. Kalkyldata'!$D$23:$D$28) -> 0
B18: ='Kontoplan RR'!E7 -> Ombyggnad | E18: =SUMIF('2. Kalkyldata'!$E$23:$E$27,LEFT('1. Framskrivningsunderlag'!$B18,3),'2. Kalkyldata'!$H$23:$H$28) -> 0 | F18: =SUMIF('2. Kalkyldata'!$E$23:$E$27,LEFT('1. Framskrivningsunderlag'!$B18,3),'2. Kalkyldata'!$W$23:$W$28) -> 0 | G18: =IFERROR($M18/E18,0) -> 0 | K18: =SUMIF('2. Kalkyldata'!$E$23:$E$27,LEFT('1. Framskrivningsunderlag'!$B18,3),'2. Kalkyldata'!$H$23:$H$28) -> 0 | L18: =IFERROR($K18/$P18,0) -> 0 | M18: =SUMIF('2. Kalkyldata'!$E$23:$E$27,LEFT('1. Framskrivningsunderlag'!$B18,3),'2. Kalkyldata'!$W$23:$W$28) -> 0 | N18: =IFERROR($M18/$K18,0) -> 0 | O18: =IFERROR($E18/$P18,0) -> 0 | P18: =SUMIF('2. Kalkyldata'!$E$23:$E$27,LEFT('1. Framskrivningsunderlag'!$B18,3),'2. Kalkyldata'!$D$23:$D$28) -> 0 | R18: 10. Dolt flikarna "6. Ack. Kapitalutlägg" och "7. Diagram" då funktionerna och nyckeltalen inte efterfrågas. Vid behov högerklicka på valfri flik och välj "Ta fram" | S18: JW
B19: ='Kontoplan RR'!E8 -> Nybyggnad | E19: =SUMIF('2. Kalkyldata'!$E$23:$E$27,LEFT('1. Framskrivningsunderlag'!$B19,3),'2. Kalkyldata'!$H$23:$H$28) -> 6100 | F19: =SUMIF('2. Kalkyldata'!$E$23:$E$27,LEFT('1. Framskrivningsunderlag'!$B19,3),'2. Kalkyldata'!$W$23:$W$28) -> 2.4e+08 | G19: =IFERROR($M19/E19,0) -> 39344.262 | K19: =SUMIF('2. Kalkyldata'!$E$23:$E$27,LEFT('1. Framskrivningsunderlag'!$B19,3),'2. Kalkyldata'!$H$23:$H$28) -> 6100 | L19: =IFERROR($K19/$P19,0) -> 0 | M19: =SUMIF('2. Kalkyldata'!$E$23:$E$27,LEFT('1. Framskrivningsunderlag'!$B19,3),'2. Kalkyldata'!$W$23:$W$28) -> 2.4e+08 | N19: =IFERROR($M19/$K19,0) -> 39344.262 | O19: =IFERROR($E19/$P19,0) -> 0 | P19: =SUMIF('2. Kalkyldata'!$E$23:$E$27,LEFT('1. Framskrivningsunderlag'!$B19,3),'2. Kalkyldata'!$D$23:$D$28) -> 0 | R19: 11. 2023-02-15 Justering av rubriker under "Projektbeskrivning" (borttagning av två kolumner: "Investering per plats" samt "BRA / plats" | S19: JW
B20: ='Kontoplan RR'!E9 -> Installationer | E20: =SUMIF('2. Kalkyldata'!$E$23:$E$27,LEFT('1. Framskrivningsunderlag'!$B20,3),'2. Kalkyldata'!$H$23:$H$28) -> 0 | F20: =SUMIF('2. Kalkyldata'!$E$23:$E$27,LEFT('1. Framskrivningsunderlag'!$B20,3),'2. Kalkyldata'!$W$23:$W$28) -> 0 | G20: =IFERROR($M20/E20,0) -> 0 | K20: =SUMIF('2. Kalkyldata'!$E$23:$E$27,LEFT('1. Framskrivningsunderlag'!$B20,3),'2. Kalkyldata'!$H$23:$H$28) -> 0 | L20: =IFERROR($K20/$P20,0) -> 0 | M20: =SUMIF('2. Kalkyldata'!$E$23:$E$27,LEFT('1. Framskrivningsunderlag'!$B20,3),'2. Kalkyldata'!$W$23:$W$28) -> 0 | N20: =IFERROR($M20/$K20,0) -> 0 | O20: =IFERROR($E20/$P20,0) -> 0 | P20: =SUMIF('2. Kalkyldata'!$E$23:$E$27,LEFT('1. Framskrivningsunderlag'!$B20,3),'2. Kalkyldata'!$D$23:$D$28) -> 0 | R20: 12. Bytt ut driftkostnadsposterna och döpt dem efter hur Lejonfastigheter är vana att fördela dem. | S20: JW
B21: ='Kontoplan RR'!E10 -> Mark | E21: =SUMIF('2. Kalkyldata'!$E$23:$E$27,LEFT('1. Framskrivningsunderlag'!$B21,3),'2. Kalkyldata'!$H$23:$H$28) -> 0 | F21: =SUMIF('2. Kalkyldata'!$E$23:$E$27,LEFT('1. Framskrivningsunderlag'!$B21,3),'2. Kalkyldata'!$W$23:$W$28) -> 0 | G21: =IFERROR($M21/E21,0) -> 0 | K21: =SUMIF('2. Kalkyldata'!$E$23:$E$27,LEFT('1. Framskrivningsunderlag'!$B21,3),'2. Kalkyldata'!$H$23:$H$28) -> 0 | L21: =IFERROR($K21/$P21,0) -> 0 | M21: =SUMIF('2. Kalkyldata'!$E$23:$E$27,LEFT('1. Framskrivningsunderlag'!$B21,3),'2. Kalkyldata'!$W$23:$W$28) -> 0 | N21: =IFERROR($M21/$K21,0) -> 0 | O21: =IFERROR($E21/$P21,0) -> 0 | P21: =SUMIF('2. Kalkyldata'!$E$23:$E$27,LEFT('1. Framskrivningsunderlag'!$B21,3),'2. Kalkyldata'!$D$23:$D$28) -> 0 | R21: 13. Börjat lägga till kommentarer av karaktären "Lathund". | S21: JW
B22: Summa investering | E22: =SUM(E17:E21) -> 6100 | F22: =SUM(F17:F21) -> 2.4e+08 | G22: =IFERROR($M22/D22,0) -> 0 | K22: =SUM(K17:K21) -> 6100 | L22: =IFERROR($K22/$P22,0) -> 0 | M22: =SUM(M17:M21) -> 2.4e+08 | N22: =IFERROR($M22/$K22,0) -> 39344.262 | O22: =IFERROR($E22/$P22,0) -> 0 | P22: =SUM(P17:P21) -> 0 | R22: 14. Justerat benämning av "Ränta" under 3.Finansiering" till Byggnadskreditiv, då vi inte har annan ränta att härleda | S22: JW
B23: Därutöver re-investeringar/hyressatt underhåll | F23: =IFERROR('2. Kalkyldata'!$X$39/'2. Kalkyldata'!$H$28,0) -> 0 | M23: ='2. Kalkyldata'!$X$39 -> 0 | R23: 15. Diverse malljusteringar 2024 | S23: JW
B24: Därutöver planerat underhåll | F24: 0 | R24: 16. 2026-09-30 v3: Restvärde = rent marknadsvärde vid justerad direktavkastning (flik 2 sektion 5, vikter 0/1/0 på flik 5). Bef-objekt = nollalternativ: krav 1–2 på tillkommande flöde (flik 4 rad 64–82), krav 3 på hela fastigheten, egen avskrivningstid för befintligt bokfört värde. Investeringsspecifikation som matris (sektion 4) styr Budget kr/kvm. Känslighet restvärde ±1,00 pp (flik 5 rad 53–61, flik 1). Kravhyra som output (flik 2 rad 17 / kolumn V, datatabell AC14:AI16). | S24: Claude/JW
B25: Total projektvolym | F25: =F22+F23+F24 -> 2.4e+08 | N25: ='2. Kalkyldata'!$X$39/'2. Kalkyldata'!$H$28 -> 0 | R25: 17. 2026-10-09 v3.1: Ett restvärde i alla krav (flik 4 rad 84–90: driftnetto år N+1, fullt uthyrt, exkl extraordinärt UH, / justerad yield). Kalkylränta restvärde = extern yield + inflation. Vakansfaktorn egen skala −0,25…+2,00 pp med ekvivalent vakans. Vakansgrad bara år efter avtal inom kalkylperioden (spärr + notis). Extraordinärt UH t.o.m. horisonten. | S25: Claude/JW
R26: 18. 2026-10-11 v3.2: Användarvänlighet och design efter agentgranskning — inmatningsmeddelanden på alla inmatningsfält, krav 1/2/3 namngivna överallt, två decimaler på räntor/IRR, stavfel och engelska rester rättade, arbetsgång på flik 2, källhänvisningar mellan flikar, hjälprader dolda, utskrift (sidbrytning flik 1, årsrubrik och sidordning flik 4), sidfot v3.2. Inga beräkningar ändrade. | S26: Claude/JW
B27: Projektbeskrivning:
B28: Fyll i
B35: Bild – klistra in här | E35: Karta – klistra in här
B54: Marknadssituation
B55: Marknadsvärde (senaste fastighetsvärdering) | G55: 0
B57: Kommentar marknadssituation och restvärde: | K57: Byggrätter | O57: Före projekt | P57: Efter projekt
B58: Hur har restvärdet bedömts (direktavkastning, kalkylränta)? Har värderaren tagit hänsyn till kommande investeringar för att upprätthålla hyresnivån? Vad händer med marknadsvärdet om vi inte investerar? Kommentera sannolikt scenario, t.ex. sjukt hus, tekniskt utdömt eller vakanser. Är byggrätterna optimerade? Förändras momsregistreringsgraden? | K58: Utnyttjade byggrätter | O58: 0 | P58: 0
K59: Outnyttjade byggrätter | O59: 0 | P59: 0
K60: Summa | O60: =SUM(O58:O59) -> 0 | P60: =SUM(P58:P59) -> 0
B65: ="Restvärdesbedömning — direktavkastning vid exit "&ROUND('2. Kalkyldata'!$M$11*100,2)&" % (marknad "&ROUND('2. Kalkyldata'!$M$6*100,2)&" % "&IF('2. Kalkyldata'!$M$10>=0,"+","")&ROUND('2. Kalkyldata'!$M$10*100,2)&" pp)" -> Restvärdesbedömning — direktavkastning vid exit 6,5 % (marknad 6,5 % +0 pp)
B66: Scenario | C66: Direktavk. | D66: IRR före skatt | E66: Restvärde (exit) | F66: Kravhyra, kr/kvm | G66: NPV tillkommande
B67: ='5. IRR'!B55 -> Optimistisk (−1,00 pp) | C67: ='5. IRR'!C55 -> 0.055 | D67: ='5. IRR'!E55 -> 0.087247261 | E67: ='5. IRR'!D55 -> 3.2138364e+08 | F67: ='5. IRR'!H55 -> 2480 | G67: ='5. IRR'!F55 -> 19970000
B68: ='5. IRR'!B56 -> Bedömt (2. Kalkyldata sektion 5) | C68: ='5. IRR'!C56 -> 0.065 | D68: ='5. IRR'!E56 -> 0.080803743 | E68: ='5. IRR'!D56 -> 271940000 | F68: ='5. IRR'!H56 -> 2559 | G68: ='5. IRR'!F56 -> 10300000
B69: ='5. IRR'!B57 -> Pessimistisk (+1,00 pp) | C69: ='5. IRR'!C57 -> 0.075 | D69: ='5. IRR'!E57 -> 0.075506366 | E69: ='5. IRR'!D57 -> 2.3568133e+08 | F69: ='5. IRR'!H57 -> 2621 | G69: ='5. IRR'!F57 -> 3200000
B71: Känslighet: direktavkastningen vid exit ±1,00 pp. Raden Bedömt är kalkylens restvärde (4. NPV rad 84–90).
...

Sheet 2. Kalkyldata
B1: INMATNING | C1: Arbetsgång: 1) Projektuppgifter på 1. Framskrivningsunderlag. 2) Blå fält här uppifrån och ned: kalkylstart och förutsättningar (1) → ytor, hyror och avtal (2) → drift (3) → investering per objekt (4) → restvärdesbedömning (5). 3) Läs resultatet i Nyckeltal kalkyl (rad 12–17) och på flik 1.
C2: Flik 3–7 räknas automatiskt; 3. Finansiering ändras bara efter OK från finansansvarig. Röd kolumnrubrik = obligatoriskt fält som saknar värde.
C3: FASTIGHETS- OCH MARKNADSFÖRUTSÄTTNINGAR | K3: KALKYLSTART | M3: 2026
A4: 1 | C4: Projektinfo — hämtas från flik 1 (fyll i där) | K4: Förutsättningar marknad | N4: Förutsättningar fastighet | S4: Avskrivning | AC4: Skala restvärdesbedömning | AK4: Skala långsiktig vakansrisk (pp)
C5: ='1. Framskrivningsunderlag'!$B$3 -> Projektnamn | E5: Fastighet | G5: Objekt | H5: BTA | I5: BRA | J5: Fastighetsarea | M5: =P5 -> 2026 | P5: =IF(M3<>"",M3,YEAR('3. Finansiering'!C1)) -> 2026 | Q5: =P5+10 -> 2036 | R5: =Q5+10 -> 2046 | S5: Del | T5: Avskrivning, %/år | U5: Värde (tkr) | AC5: Mycket positivt | AK5: Låg | AL5: -0.0025
C6: Fastighet: | E6: ='1. Framskrivningsunderlag'!$G$5 -> Fyll i | G6: ='1. Framskrivningsunderlag'!$G$6 -> Fyll i | H6: ='1. Framskrivningsunderlag'!G10 -> Fyll i | I6: ='1. Framskrivningsunderlag'!$G$9 -> Fyll i | J6: ='1. Framskrivningsunderlag'!$G$8 -> Fyll i | K6: Direktavkastningskrav, marknad | M6: 0.065 | N6: Tomträttsavgäld, kr/år | P6: 0 | Q6: 0 | R6: 0 | S6: Mark | T6: 0 | U6: 0 | AC6: Något positivt | AK6: Normal | AL6: 0
K7: Kalkylränta driftnetto | M7: 0.0455 | N7: Taxeringsvärde, kr | P7: 0 | Q7: 0 | R7: 0 | S7: Byggnad | T7: 0.03 | U7: 0 | AC7: Neutralt | AK7: Förhöjd | AL7: 0.005
C8: Typ av åtgärd: | E8: ='1. Framskrivningsunderlag'!$G$11 -> Fyll i | K8: Kalkylränta restvärde | M8: =$M$6+$M$9 -> 0.085 | N8: Fastighetsskatt, % | P8: 0 | S8: Övrigt 1 | T8: 0.03 | U8: 0 | AC8: Något negativt | AK8: Hög | AL8: 0.01
K9: Inflation | M9: 0.02 | N9: Bokfört värde, kr | P9: 0 | S9: Övrigt 2 | T9: 0 | U9: 0 | AC9: Mycket negativt | AK9: Mycket hög | AL9: 0.02
C10: Momsregistreringsgrad före | F10: ='1. Framskrivningsunderlag'!$G$12 -> Fyll i | K10: Justering (från sektion 5) | M10: =$H$79 -> 0 | N10: Bokfört värde - proj belastning | P10: 0 | Q10: Fr.o.m. år | R10: T.o.m. år | S10: Summa | T10: =IFERROR(SUMPRODUCT(T6:T9,U6:U9)/U10,"") | U10: =SUM(U6:U9) -> 0
C11: Momsregistreringsgrad efter | F11: ='1. Framskrivningsunderlag'!$G$13 -> Fyll i | K11: Justerad direktavkastning | M11: =$M$6+$M$10 -> 0.065 | N11: Ersättningslokaler, kr/år | P11: 0
C12: Nyckeltal kalkyl | D12: Resultat | F12: Krav | G12: Notiser | N12: Tillfälliga intäkter, kr/år | P12: 0 | AC12: Hyresmultiplikator m — teknisk cell för datatabellen, lämna 1 | AD12: 1
C13: NPV tillkommande (krav 1) | D13: =IF(G13<>"","",'4. NPV'!$E$82/1000) -> 10300 | F13: >0 | G13: =IF(COUNTA(M3,M6,M7,M9,Q15,Q17,C23:C27,E23:E27,F23:F27,G23:G27,I23:I27,J23:J27,M23:M27,N23:N27,O23:O27,Q23:Q27,S23:S27,R23:R27)<17,"Fyll i alla tvingande fält",IF(SUMPRODUCT(--($H$23:$H$27>0),--($E$23:$E$27<>"Bef"),--($T$23:$T$27=0))>0,"Investering saknas för objekt med area (sektion 4)",IF($AD$12<>1,"Hyresmultiplikator AD12 ≠ 1",""))) | I13: =IF(SUM(G39:H39)=0,"Inga driftkostnader angivna","") | N13: Avskr.tid befintligt | P13: =IF(Q13<>0,Q13,P16) -> 33 | R13: ← egen tid, år (valfri) | AC13: m | AD13: NPV tillk. | AE13: NPV vid IRR-krav | AF13: NPV tillk. opt | AG13: NPV tillk. pess | AH13: NPV vid krav, opt | AI13: NPV vid krav, pess
C14: IRR före skatt (krav 2) | D14: =IF('5. IRR'!D40="N/A"," ",'5. IRR'!D40) -> 0.080803743 | F14: 0.0634 | G14: =IF('5. IRR'!C11<>"","Eget restvärde ifyllt i 5. IRR. ","")&IF(M10<>0,"Yield "&IF(M10>0,"+","")&ROUND(M10*100,2)&" pp → "&ROUND(M11*100,2)&" %","") | I14: =IF(SUM(G39:H39)>0,IF(AND(H39=0,G28<>0),"Driftkostnad ev. angiven på fel yta",""),"") | K14: Vakans efter avtal, viktad | M14: =IFERROR(P28,"") -> 0 | N14: Central administration | P14: 80 | Q14: Justering | AD14: ='4. NPV'!$E$82 -> 10300000 | AE14: ='5. IRR'!$D$37+NPV('2. Kalkyldata'!$F$14,'5. IRR'!$E$37:$BA$37) -> 33005083 | AF14: ='5. IRR'!$F$55 -> 19970000 | AG14: ='5. IRR'!$F$57 -> 3200000 | AH14: ='5. IRR'!$D$59+NPV('2. Kalkyldata'!$F$14,'5. IRR'!$E$59:$BA$59) -> 48382166 | AI14: ='5. IRR'!$D$61+NPV('2. Kalkyldata'!$F$14,'5. IRR'!$E$61:$BA$61) -> 21728556
C15: PV mot bokfört värde (krav 3) | D15: =IF(G13<>"","",('4. NPV'!E52-('2. Kalkyldata'!$P$9+'2. Kalkyldata'!$X$28-'2. Kalkyldata'!$P$10))/1000) -> 10300 | F15: >0 | I15: =IF(OR(AND(M23<>0,M23<$M$3),AND(M24<>0,M24<$M$3),AND(M25<>0,M25<$M$3),AND(M26<>0,M26<$M$3),AND(M27<>0,M27<$M$3)),"Glapp, Avtalstid / Kalkylstart","") | N15: Årlig avskrivning | P15: =IF(Q15<>"",Q15,'2. Kalkyldata'!T10) -> 0.03 | Q15: 0.03 | S15: Minsta möjliga markvärde | AC15: 0 | AD15: -288810000 | AE15: -2.827158e+08 | AF15: -290820000 | AG15: -287340000 | AH15: -2.8590951e+08 | AI15: -2.8037374e+08
C16: Pay-off tid | D16: ='4. NPV'!$C$62 -> 15 | I16: =IF(OR(AND(R23<>0,R23<M23),AND(R24<>0,R24<M24),AND(R25<>0,R25<M25),AND(R26<>0,R26<M26),AND(R27<>0,R27<M27)),"Glapp, Prod.avslut / Avtalstid","") | K16: Bolagsskatt | M16: 0.206 | N16: Avskrivningstid | P16: =(FLOOR(100%/P15,1)) -> 33 | S16: Markareal | T16: kr/kvm | U16: Minsta värde | AC16: 1 | AD16: 10300000 | AE16: 33005083 | AF16: 19970000 | AG16: 3200000 | AH16: 48382166 | AI16: 21728556
C17: Kravhyra krav 1–2, kr/kvm | D17: =IF(G13<>"","",CEILING($AD$19*$AD$20,1)) -> 2559 | F17: =IF(G13<>"","",LEFT($AE$19,3)) -> NPV | I17: =IF(OR(AND(M23<>0,M23<R23),AND(M24<>0,M24<R24),AND(M25<>0,M25<R25),AND(M26<>0,M26<R26),AND(M27<>0,M27<R27)),"Glapp, Avtalstid / Prod.avslut. ","")&IF(G13<>"","",IF(D17>$AD$20,"Höj hyran "&ROUND(D17-$AD$20,0)&" kr/kvm för krav 1–2. ",""))&IF(COUNTIF(E23:E27,"Bef")+(P9>0)>0,"Bef/bokfört värde ingår bara i krav 3. ","")&IF(SUMPRODUCT(($P$23:$P$27>0)*(AM23:AM27=FALSE))>0,"Vakansgrad utan effekt — avtalet täcker kalkylperioden (se sektion 5).","") | N17: Kalkylperiod | P17: =IF(Q17<>0,Q17,(FLOOR(100%/P15,1))) -> 20 | Q17: 20 | S17: =J6 -> Fyll i | U17: =IFERROR($T$17*$J$6,0) -> 0
AC18: m per krav → | AD18: =IFERROR(-AD15/(AD16-AD15),1) -> 0.96556451 | AE18: =IFERROR(-AE15/(AE16-AE15),1) -> 0.8954612 | AF18: =IFERROR(-AF15/(AF16-AF15),1) -> 0.93574439 | AG18: =IFERROR(-AG15/(AG16-AG15),1) -> 0.98898603 | AH18: =IFERROR(-AH15/(AH16-AH15),1) -> 0.85526961 | AI18: =IFERROR(-AI15/(AI16-AI15),1) -> 0.9280755
C19: INTÄKTER OCH INVESTERINGAR | AC19: m* = MAX(krav 1, krav 2): bedömt | bindande | opt | pess | AD19: =MAX(AD18,AE18) -> 0.96556451 | AE19: =IF(AD18>=AE18,"NPV binder","IRR binder") -> NPV binder | AF19: =MAX(AF18,AH18) -> 0.93574439 | AG19: =MAX(AG18,AI18) -> 0.98898603 | AS19: Hjälptabeller - Ignorera dessa
C20: Ett objekt per rad (högst 5). Hyror i kr/kvm och år, kalkylstartens penningvärde. Budget kr/kvm räknas fram från sektion 4. | AC20: Angiven hyra, viktad kr/kvm (icke-Bef) | AD20: =IFERROR(SUMPRODUCT(--($E$23:$E$27<>"Bef"),$I$23:$I$27,$H$23:$H$27)/SUMPRODUCT(--($E$23:$E$27<>"Bef"),$H$23:$H$27),0) -> 2650
A21: 2 | C21: Ytor | F21: Area (BRA) | I21: Hyresvillkor | M21: Avtalsperiod | O21: Marknadshyra | P21: Vakansgrad | Q21: Investeringar | W21: Investering, kr | Y21: Bokfört värde
C22: Byggnad/lokal/objekt | D22: Antal platser | E22: Typ | F22: Befintligt | G22: Nybyggnad/ Tillbyggnad | H22: Totalt | I22: Hyra, kr/kvm | J22: Index, andel av inflation | K22: Tillägg, kr/kvm | L22: Totalhyra, kr/år | M22: Fr.o.m. år | N22: T.o.m. år | O22: =CONCATENATE(P5," kr/kvm") -> 2026 kr/kvm | P22: efter avtal, inom kalkylperioden | Q22: Produktions- start | R22: Produktions- avslut | S22: =CONCATENATE("Budget kr/kvm ",$R23) -> Budget kr/kvm 2026 | T22: Totalt kr/kvm | U22: Justering, kr/kvm | W22: Total investering | X22: PV exkl projektbelast | Y22: =CONCATENATE(" Budget inkl projektbelast.") -> Budget inkl projektbelast. | Z22: Bokfört värde kr/kvm | AA22: Varav bokfört värde | AC22: =M3 -> 2026 | AD22: =AC22+1 -> 2027 | AE22: =AD22+1 -> 2028 | AF22: =AE22+1 -> 2029 | AG22: =AF22+1 -> 2030 | AH22: =AG22+1 -> 2031 | AI22: =AH22+1 -> 2032 | AJ22: =AI22+1 -> 2033 | AK22: =AJ22+1 -> 2034 | AM22: Vakansgrad tillåten (avtal slutar före kalkylperiodens sista år) | AS22: =$M$5 -> 2026 | AT22: =AS22+1 -> 2027 | AU22: =AT22+1 -> 2028 | AV22: =AU22+1 -> 2029 | AW22: =AV22+1 -> 2030 | AX22: =AW22+1 -> 2031 | AY22: =AX22+1 -> 2032 | AZ22: =AY22+1 -> 2033 | BA22: =AZ22+1 -> 2034 | ... BZ22: =BY22+1 -> 2059
C23: Skola | E23: Nyb | G23: 6100 | H23: =SUM(F23:G23) -> 6100 | I23: 2650 | J23: 0.7 | L23: =((H23*I23*IF($E23="Bef",1,$AD$12))+(K23*H23)) -> 16165000 | M23: 2026 | N23: 2045 | O23: =I23*IF($E23="Bef",1,$AD$12) -> 2650 | Q23: 2026 | R23: 2026 | S23: =IFERROR(G$69/$H23,0) -> 39344.262 | T23: =IF(U23="",S23,U23) -> 39344.262 | W23: =IFERROR((T23*$H23),0) -> 2.4e+08 | X23: =$W23/((1+$M$9)^MAX(0,$R23-$M$5)) -> 2.4e+08 | Y23: =IFERROR((X23+(Z23*$H23)),0) -> 2.4e+08 | Z23: =IF(OR($E23="Bef",$E23=""),0,$P$10/($H$28-SUMIF($E$23:$E$27,"Bef",$H$23:$H$27))) -> 0 | AA23: =$Z23*$H23 -> 0 | AM23: =OR(N23="",N23<$P$5+$P$17-1) -> FALSE | AS23: =IF(AS$22=$R23,$S23*$H23,0) -> 2.4e+08 | AT23: =IF(AT$22=$R23,$S23*$H23,0) -> 0 | AU23: =IF(AU$22=$R23,$S23*$H23,0) -> 0 | AV23: =IF(AV$22=$R23,$S23*$H23,0) -> 0 | AW23: =IF(AW$22=$R23,$S23*$H23,0) -> 0 | AX23: =IF(AX$22=$R23,$S23*$H23,0) -> 0 | AY23: =IF(AY$22=$R23,$S23*$H23,0) -> 0 | AZ23: =IF(AZ$22=$R23,$S23*$H23,0) -> 0 | ... BZ23: =IF(BZ$22=$R23,$S23*$H23,0) -> 0
H24: =SUM(F24:G24) -> 0 | L24: =((H24*I24*IF($E24="Bef",1,$AD$12))+(K24*H24)) -> 0 | O24: =I24*IF($E24="Bef",1,$AD$12) -> 0 | S24: =IFERROR(H$69/$H24,0) -> 0 | T24: =IF(U24="",S24,U24) -> 0 | W24: =IFERROR((T24*$H24),0) -> 0 | X24: =$W24/((1+$M$9)^MAX(0,$R24-$M$5)) -> 0 | Y24: =IFERROR((X24+(Z24*$H24)),0) -> 0 | Z24: =IF(OR($E24="Bef",$E24=""),0,$P$10/($H$28-SUMIF($E$23:$E$27,"Bef",$H$23:$H$27))) -> 0 | AA24: =$Z24*$H24 -> 0 | AM24: =OR(N24="",N24<$P$5+$P$17-1) -> TRUE | AS24: =IF(AS$22=$R24,$S24*$H24,0) -> 0 | AT24: =IF(AT$22=$R24,$S24*$H24,0) -> 0 | AU24: =IF(AU$22=$R24,$S24*$H24,0) -> 0 | AV24: =IF(AV$22=$R24,$S24*$H24,0) -> 0 | AW24: =IF(AW$22=$R24,$S24*$H24,0) -> 0 | AX24: =IF(AX$22=$R24,$S24*$H24,0) -> 0 | AY24: =IF(AY$22=$R24,$S24*$H24,0) -> 0 | AZ24: =IF(AZ$22=$R24,$S24*$H24,0) -> 0 | ... BZ24: =IF(BZ$22=$R24,$S24*$H24,0) -> 0
H25: =SUM(F25:G25) -> 0 | L25: =((H25*I25*IF($E25="Bef",1,$AD$12))+(K25*H25)) -> 0 | O25: =I25*IF($E25="Bef",1,$AD$12) -> 0 | S25: =IFERROR(I$69/$H25,0) -> 0 | T25: =IF(U25="",S25,U25) -> 0 | W25: =IFERROR((T25*$H25),0) -> 0 | X25: =$W25/((1+$M$9)^MAX(0,$R25-$M$5)) -> 0 | Y25: =IFERROR((X25+(Z25*$H25)),0) -> 0 | Z25: =IF(OR($E25="Bef",$E25=""),0,$P$10/($H$28-SUMIF($E$23:$E$27,"Bef",$H$23:$H$27))) -> 0 | AA25: =$Z25*$H25 -> 0 | AM25: =OR(N25="",N25<$P$5+$P$17-1) -> TRUE | AS25: =IF(AS$22=$R25,$S25*$H25,0) -> 0 | AT25: =IF(AT$22=$R25,$S25*$H25,0) -> 0 | AU25: =IF(AU$22=$R25,$S25*$H25,0) -> 0 | AV25: =IF(AV$22=$R25,$S25*$H25,0) -> 0 | AW25: =IF(AW$22=$R25,$S25*$H25,0) -> 0 | AX25: =IF(AX$22=$R25,$S25*$H25,0) -> 0 | AY25: =IF(AY$22=$R25,$S25*$H25,0) -> 0 | AZ25: =IF(AZ$22=$R25,$S25*$H25,0) -> 0 | ... BZ25: =IF(BZ$22=$R25,$S25*$H25,0) -> 0
H26: =SUM(F26:G26) -> 0 | L26: =((H26*I26*IF($E26="Bef",1,$AD$12))+(K26*H26)) -> 0 | O26: =I26*IF($E26="Bef",1,$AD$12) -> 0 | S26: =IFERROR(J$69/$H26,0) -> 0 | T26: =IF(U26="",S26,U26) -> 0 | W26: =IFERROR((T26*$H26),0) -> 0 | X26: =$W26/((1+$M$9)^MAX(0,$R26-$M$5)) -> 0 | Y26: =IFERROR((X26+(Z26*$H26)),0) -> 0 | Z26: =IF(OR($E26="Bef",$E26=""),0,$P$10/($H$28-SUMIF($E$23:$E$27,"Bef",$H$23:$H$27))) -> 0 | AA26: =$Z26*$H26 -> 0 | AM26: =OR(N26="",N26<$P$5+$P$17-1) -> TRUE | AS26: =IF(AS$22=$R26,$S26*$H26,0) -> 0 | AT26: =IF(AT$22=$R26,$S26*$H26,0) -> 0 | AU26: =IF(AU$22=$R26,$S26*$H26,0) -> 0 | AV26: =IF(AV$22=$R26,$S26*$H26,0) -> 0 | AW26: =IF(AW$22=$R26,$S26*$H26,0) -> 0 | AX26: =IF(AX$22=$R26,$S26*$H26,0) -> 0 | AY26: =IF(AY$22=$R26,$S26*$H26,0) -> 0 | AZ26: =IF(AZ$22=$R26,$S26*$H26,0) -> 0 | ... BZ26: =IF(BZ$22=$R26,$S26*$H26,0) -> 0
H27: =SUM(F27:G27) -> 0 | L27: =((H27*I27*IF($E27="Bef",1,$AD$12))+(K27*H27)) -> 0 | O27: =I27*IF($E27="Bef",1,$AD$12) -> 0 | S27: =IFERROR(K$69/$H27,0) -> 0 | T27: =IF(U27="",S27,U27) -> 0 | W27: =IFERROR((T27*$H27),0) -> 0 | X27: =$W27/((1+$M$9)^MAX(0,$R27-$M$5)) -> 0 | Y27: =IFERROR((X27+(Z27*$H27)),0) -> 0 | Z27: =IF(OR($E27="Bef",$E27=""),0,$P$10/($H$28-SUMIF($E$23:$E$27,"Bef",$H$23:$H$27))) -> 0 | AA27: =$Z27*$H27 -> 0 | AM27: =OR(N27="",N27<$P$5+$P$17-1) -> TRUE | AS27: =IF(AS$22=$R27,$S27*$H27,0) -> 0 | AT27: =IF(AT$22=$R27,$S27*$H27,0) -> 0 | AU27: =IF(AU$22=$R27,$S27*$H27,0) -> 0 | AV27: =IF(AV$22=$R27,$S27*$H27,0) -> 0 | AW27: =IF(AW$22=$R27,$S27*$H27,0) -> 0 | AX27: =IF(AX$22=$R27,$S27*$H27,0) -> 0 | AY27: =IF(AY$22=$R27,$S27*$H27,0) -> 0 | AZ27: =IF(AZ$22=$R27,$S27*$H27,0) -> 0 | ... BZ27: =IF(BZ$22=$R27,$S27*$H27,0) -> 0
C28: Totalt | D28: =SUM($D$23:$D$27) -> 0 | F28: =SUM(F23:F27) -> 0 | G28: =SUM(G23:G27) -> 6100 | H28: =F28+G28 -> 6100 | L28: =SUM(L23:L27) -> 16165000 | O28: =(O23*H23+O24*H24+O25*H25+O26*H26+O27*H27) -> 16165000 | P28: =IFERROR(SUMPRODUCT(P23:P27,L23:L27)/L28,"") -> 0 | S28: =IF(H28=0,"",S29*H28) -> 2.4e+08 | T28: =IF(H28=0,"",T29*H28) -> 2.4e+08 | U28: =IF(H29=0,"",U29*H28) | W28: =SUM(W23:W27) -> 2.4e+08 | X28: =SUM(X23:X27) -> 2.4e+08 | Y28: =SUM(Y23:Y27) -> 2.4e+08 | Z28: =IF(H29=0,"",Z29*H28) | AA28: =SUM(AA23:AA27) -> 0 | AS28: =SUM(AS23:AS27) -> 2.4e+08 | AT28: =SUM(AT23:AT27) -> 0 | AU28: =SUM(AU23:AU27) -> 0 | AV28: =SUM(AV23:AV27) -> 0 | AW28: =SUM(AW23:AW27) -> 0 | AX28: =SUM(AX23:AX27) -> 0 | AY28: =SUM(AY23:AY27) -> 0 | AZ28: =SUM(AZ23:AZ27) -> 0 | ... BZ28: =SUM(BZ23:BZ27) -> 0
C29: Per kvm, viktat | L29: =IF(L28=0,"",L28/H28) -> 2650 | O29: =IF(O28=0,"",O28/H28) -> 2650 | S29: =IF(H28=0,"",SUMPRODUCT($S$23:$S$27,$H$23:$H$27)/$H$28) -> 39344.262 | T29: =IF(H28=0,"",SUMPRODUCT($T$23:$T$27,$H$23:$H$27)/$H$28) -> 39344.262 | U29: =IF(H29=0,"",SUMPRODUCT($U$23:$U$27,$H$23:$H$27)/$H$28) | Z29: =IF(H29=0,"",SUMPRODUCT($Z$23:$Z$27,$H$23:$H$27)/$H$28)
C31: KOSTNADER
C32: Kr/kvm och år i kalkylstartens penningvärde. Befintligt gäller objekt av typ Bef/Omb/Ins/Mar, Nybyggnad/Tillbyggnad gäller typ Nyb. Kostnadshöjning = stegvis höjning utöver inflation.
A33: 3 | C33: Drift och underhåll, kr/kvm och år | G33: Befintligt | H33: Nybyggnad/ Tillbyggnad | I33: Totalt, viktad | K33: Kostnadshöjning utöver inflation | L33: 10 | M33: 15 | N33: Total höjning | P33: Re-investering/ hyressatt UH | Q33: Byggnad/Lokal/ Objekt | R33: År | S33: =CONCATENATE("Kostnad kr/kvm ",$P$5) -> Kostnad kr/kvm 2026 | T33: Uppräknat, kr/kvm | U33: Justering | W33: Underhåll uppräknat | X33: Underhåll ,exkl uppräkning | Y33: =CONCATENATE("jmf budget kolumn ",$P$5) -> jmf budget kolumn 2026
C34: Fastighetsskötsel | G34: 0 | H34: 0 | I34: =IFERROR(SUMPRODUCT(G34:H34,$F$28:$G$28)/$H$28,0) -> 0 | K34: Fastighetsskötsel | L34: 0 | M34: 0 | N34: =L34+M34 -> 0 | T34: =IF(U34<>0,U34*((1+$M$9)^($R34-$P$5)),S34*((1+$M$9)^($R34-$P$5))) -> 0 | W34: =IFERROR(SUMIF($C$23:$C$27,$Q34,$H$23:$H$27)*$T34,"") -> 0 | X34: =IF($U34=0,$S34*SUMIF($C$23:$C$27,$Q34,$H$23:$H$27),$U34*SUMIF($C$23:$C$27,$Q34,$H$23:$H$27)) -> 0 | Y34: =IFERROR(SUMIF($C$23:$C$27,$Q34,$H$23:$H$27)*$S34,"") -> 0
C35: Reparationer | G35: 0 | H35: 0 | I35: =IFERROR(SUMPRODUCT(G35:H35,$F$28:$G$28)/$H$28,0) -> 0 | K35: Reparationer | L35: 0 | M35: 0 | N35: =L35+M35 -> 0 | T35: =IF(U35<>0,U35,S35*(1+$M$9)^($R35-$P$5)) -> 0 | W35: =IFERROR(SUMIF($C$23:$C$27,$Q35,$H$23:$H$27)*$T35,"") -> 0 | X35: =IF($U35=0,$S35*SUMIF($C$23:$C$27,$Q35,$H$23:$H$27),$U35*SUMIF($C$23:$C$27,$Q35,$H$23:$H$27)) -> 0 | Y35: =IFERROR(SUMIF($C$23:$C$27,$Q35,$H$23:$H$27)*$S35,"") -> 0
C36: Planerat underhåll | G36: 0 | H36: 0 | I36: =IFERROR(SUMPRODUCT(G36:H36,$F$28:$G$28)/$H$28,0) -> 0 | K36: Planerat underhåll | L36: 0 | M36: 0 | N36: =L36+M36 -> 0 | T36: =IF(U36<>0,U36,S36*(1+$M$9)^($R36-$P$5)) -> 0 | W36: =IFERROR(SUMIF($C$23:$C$27,$Q36,$H$23:$H$27)*$T36,"") -> 0 | X36: =IF($U36=0,$S36*SUMIF($C$23:$C$27,$Q36,$H$23:$H$27),$U36*SUMIF($C$23:$C$27,$Q36,$H$23:$H$27)) -> 0 | Y36: =IFERROR(SUMIF($C$23:$C$27,$Q36,$H$23:$H$27)*$S36,"") -> 0
C37: Media | G37: 0 | H37: 0 | I37: =IFERROR(SUMPRODUCT(G37:H37,$F$28:$G$28)/$H$28,0) -> 0 | K37: Media | L37: 0 | M37: 0 | N37: =L37+M37 -> 0 | T37: =IF(U37<>0,U37,S37*(1+$M$9)^($R37-$P$5)) -> 0 | W37: =IFERROR(SUMIF($C$23:$C$27,$Q37,$H$23:$H$27)*$T37,"") -> 0 | X37: =IF($U37=0,$S37*SUMIF($C$23:$C$27,$Q37,$H$23:$H$27),$U37*SUMIF($C$23:$C$27,$Q37,$H$23:$H$27)) -> 0 | Y37: =IFERROR(SUMIF($C$23:$C$27,$Q37,$H$23:$H$27)*$S37,"") -> 0
C38: Övriga förvaltningskostnader | G38: 0 | H38: 405 | I38: =IFERROR(SUMPRODUCT(G38:H38,$F$28:$G$28)/$H$28,0) -> 405 | K38: Övr. förvaltning | L38: 0 | M38: 0 | N38: =L38+M38 -> 0 | T38: =IF(U38<>0,U38,S38*(1+$M$9)^($R38-$P$5)) -> 0 | W38: =IFERROR(SUMIF($C$23:$C$27,$Q38,$H$23:$H$27)*$T38,"") -> 0 | X38: =IF($U38=0,$S38*SUMIF($C$23:$C$27,$Q38,$H$23:$H$27),$U38*SUMIF($C$23:$C$27,$Q38,$H$23:$H$27)) -> 0 | Y38: =IFERROR(SUMIF($C$23:$C$27,$Q38,$H$23:$H$27)*$S38,"") -> 0
C39: Summa kostnader | G39: =SUM(G34:G38) -> 0 | H39: =SUM(H34:H38) -> 405 | I39: =IFERROR(SUMPRODUCT(G39:H39,$F$28:$G$28)/$H$28,0) -> 405 | K39: =C39 -> Summa kostnader | L39: =IFERROR(SUMPRODUCT(L34:L38,$I$34:$I$38)/$I$39,0) -> 0 | M39: =IFERROR(SUMPRODUCT(M34:M38,$I$34:$I$38)/$I$39,0) -> 0 | N39: =IFERROR(SUMPRODUCT(N34:N38,$I$34:$I$38)/$I$39,0) -> 0 | T39: =IF(U39<>0,U39,S39*(1+$M$9)^($R39-$P$5)) -> 0 | W39: =SUM(W34:W38) -> 0 | X39: =SUM(X34:X38) -> 0 | Y39: =SUM(Y34:Y38) -> 0
C42: Beskriv antaganden: motivera otydliga poster och särskilda antaganden.
C52: INVESTERINGSSPECIFIKATION
...

Sheet 3. Finansiering
B1: Datum | C1: =NOW() -> 46306.928
B3: FINANSIERING OCH AVSKRIVNING
B4: Finansieringsantagandena (ränta, amortering, belåningsgrad) matas in i C7:C10 och ändras endast efter OK från ansvarig för bolagets finansiering. Fliken räknar fram lån, räntekostnad och amortering per år samt bokfört värde och avskrivning. Eget kapital, skuld, ränta, amortering, avskrivning och bokfört värde används i 5. IRR; investeringen per år i 4. NPV.
B6: Finansiering | C6: Inmatning | D6: Innebär
B7: Ränta byggnadskreditiv (år 1) | C7: 0.0307
B8: Långsiktig ränta | C8: 0.0455 | D8: Nås år 11
B9: Amortering per år | C9: 0.03 | D9: =(FLOOR(100%/C9,1)) -> 33
B10: Belåningsgrad | C10: 0.37
D12: ='4. NPV'!D3 -> <=2026 | E12: ='4. NPV'!E3 -> <=2027 | F12: ='4. NPV'!F3 -> <=2028 | G12: ='4. NPV'!G3 -> <=2029 | H12: ='4. NPV'!H3 -> <=2030 | I12: ='4. NPV'!I3 -> <=2031 | J12: ='4. NPV'!J3 -> <=2032 | K12: ='4. NPV'!K3 -> <=2033 | ... BA12: ='4. NPV'!BA3 -> <=
B13: År | D13: =IF(D14<='2. Kalkyldata'!$P$17+1,'2. Kalkyldata'!$P$5+C14,"") -> 2026 | E13: =IF(E14<='2. Kalkyldata'!$P$17+1,'2. Kalkyldata'!$P$5+D14,"") -> 2027 | F13: =IF(F14<='2. Kalkyldata'!$P$17+1,'2. Kalkyldata'!$P$5+E14,"") -> 2028 | G13: =IF(G14<='2. Kalkyldata'!$P$17+1,'2. Kalkyldata'!$P$5+F14,"") -> 2029 | H13: =IF(H14<='2. Kalkyldata'!$P$17+1,'2. Kalkyldata'!$P$5+G14,"") -> 2030 | I13: =IF(I14<='2. Kalkyldata'!$P$17+1,'2. Kalkyldata'!$P$5+H14,"") -> 2031 | J13: =IF(J14<='2. Kalkyldata'!$P$17+1,'2. Kalkyldata'!$P$5+I14,"") -> 2032 | K13: =IF(K14<='2. Kalkyldata'!$P$17+1,'2. Kalkyldata'!$P$5+J14,"") -> 2033 | ... BA13: =IF(BA14<='2. Kalkyldata'!$P$17+1,'2. Kalkyldata'!$P$5+AZ14,"")
B14: Kalkylår · belopp i kr | D14: 1 | E14: 2 | F14: 3 | G14: 4 | H14: 5 | I14: 6 | J14: 7 | K14: 8 | L14: 9 | M14: 10 | N14: 11 | O14: 12 | P14: 13 | Q14: 14 | R14: 15 | S14: 16 | T14: 17 | U14: 18 | V14: 19 | W14: 20 | X14: 21 | Y14: 22 | Z14: 23 | AA14: 24 | AB14: 25 | AC14: 26 | AD14: 27 | AE14: 28 | AF14: 29 | AG14: 30 | AH14: 31 | AI14: 32 | AJ14: 33 | AK14: 34 | AL14: 35 | AM14: 36 | AN14: 37 | AO14: 38 | AP14: 39 | AQ14: 40 | AR14: 41 | AS14: 42 | AT14: 43 | AU14: 44 | AV14: 45 | AW14: 46 | AX14: 47 | AY14: 48 | AZ14: 49 | BA14: 50
B15: Investering (från 2. Kalkyldata) | C15: → 4. NPV | D15: =-SUMIF('2. Kalkyldata'!AS$22,'3. Finansiering'!D13,'2. Kalkyldata'!AS$28) -> -2.4e+08 | E15: =-SUMIF('2. Kalkyldata'!AT$22,'3. Finansiering'!E13,'2. Kalkyldata'!AT$28) -> 0 | F15: =-SUMIF('2. Kalkyldata'!AU$22,'3. Finansiering'!F13,'2. Kalkyldata'!AU$28) -> 0 | G15: =-SUMIF('2. Kalkyldata'!AV$22,'3. Finansiering'!G13,'2. Kalkyldata'!AV$28) -> 0 | H15: =-SUMIF('2. Kalkyldata'!AW$22,'3. Finansiering'!H13,'2. Kalkyldata'!AW$28) -> 0 | I15: =-SUMIF('2. Kalkyldata'!AX$22,'3. Finansiering'!I13,'2. Kalkyldata'!AX$28) -> 0 | J15: =-SUMIF('2. Kalkyldata'!AY$22,'3. Finansiering'!J13,'2. Kalkyldata'!AY$28) -> 0 | K15: =-SUMIF('2. Kalkyldata'!AZ$22,'3. Finansiering'!K13,'2. Kalkyldata'!AZ$28) -> 0 | ... BA15: =-SUMIF('2. Kalkyldata'!CP$22,'3. Finansiering'!BA13,'2. Kalkyldata'!CP$28) -> 0
B16: Eget kapital per investering | C16: → 5. IRR | D16: =-D$15*(1-'3. Finansiering'!$C$10) -> 1.512e+08 | E16: =-E$15*(1-'3. Finansiering'!$C$10) -> 0 | F16: =-F$15*(1-'3. Finansiering'!$C$10) -> 0 | G16: =-G$15*(1-'3. Finansiering'!$C$10) -> 0 | H16: =-H$15*(1-'3. Finansiering'!$C$10) -> 0 | I16: =-I$15*(1-'3. Finansiering'!$C$10) -> 0 | J16: =-J$15*(1-'3. Finansiering'!$C$10) -> 0 | K16: =-K$15*(1-'3. Finansiering'!$C$10) -> 0 | ... BA16: =-BA$15*(1-'3. Finansiering'!$C$10) -> 0
B17: Belåning per investering | D17: =-'3. Finansiering'!$C$10*D$15 -> 88800000 | E17: =-'3. Finansiering'!$C$10*E$15 -> 0 | F17: =-'3. Finansiering'!$C$10*F$15 -> 0 | G17: =-'3. Finansiering'!$C$10*G$15 -> 0 | H17: =-'3. Finansiering'!$C$10*H$15 -> 0 | I17: =-'3. Finansiering'!$C$10*I$15 -> 0 | J17: =-'3. Finansiering'!$C$10*J$15 -> 0 | K17: =-'3. Finansiering'!$C$10*K$15 -> 0 | ... BA17: =-'3. Finansiering'!$C$10*BA$15 -> 0
B19: Upptagna lån | D19: =SUM($D$17:D$17) -> 88800000 | E19: =SUM($D$17:E$17) -> 88800000 | F19: =SUM($D$17:F$17) -> 88800000 | G19: =SUM($D$17:G$17) -> 88800000 | H19: =SUM($D$17:H$17) -> 88800000 | I19: =SUM($D$17:I$17) -> 88800000 | J19: =SUM($D$17:J$17) -> 88800000 | K19: =SUM($D$17:K$17) -> 88800000 | ... BA19: =SUM($D$17:BA$17) -> 88800000
B20: Amortering | C20: → 5. IRR | D20: =IF(D19>=0,D19*-'3. Finansiering'!$C$9,0) -> -2664000 | E20: =IF(E19>=0,E19*-'3. Finansiering'!$C$9,0) -> -2664000 | F20: =IF(F19>=0,F19*-'3. Finansiering'!$C$9,0) -> -2664000 | G20: =IF(G19>=0,G19*-'3. Finansiering'!$C$9,0) -> -2664000 | H20: =IF(H19>=0,H19*-'3. Finansiering'!$C$9,0) -> -2664000 | I20: =IF(I19>=0,I19*-'3. Finansiering'!$C$9,0) -> -2664000 | J20: =IF(J19>=0,J19*-'3. Finansiering'!$C$9,0) -> -2664000 | K20: =IF(K19>=0,K19*-'3. Finansiering'!$C$9,0) -> -2664000 | ... BA20: =IF(BA19>=0,BA19*-'3. Finansiering'!$C$9,0) -> -2664000
B21: Ackumulerad amortering | D21: =IF(IF(-SUM($D$20:D$20)>D19,D19,SUM($D$20:D$20))>=D19,0,(IF(-SUM($D$20:D$20)>D19,D19,SUM($D$20:D$20)))) -> -2664000 | E21: =IF(IF(-SUM($D$20:E$20)>E19,E19,SUM($D$20:E$20))>=E19,0,(IF(-SUM($D$20:E$20)>E19,E19,SUM($D$20:E$20)))) -> -5328000 | F21: =IF(IF(-SUM($D$20:F$20)>F19,F19,SUM($D$20:F$20))>=F19,0,(IF(-SUM($D$20:F$20)>F19,F19,SUM($D$20:F$20)))) -> -7992000 | G21: =IF(IF(-SUM($D$20:G$20)>G19,G19,SUM($D$20:G$20))>=G19,0,(IF(-SUM($D$20:G$20)>G19,G19,SUM($D$20:G$20)))) -> -10656000 | H21: =IF(IF(-SUM($D$20:H$20)>H19,H19,SUM($D$20:H$20))>=H19,0,(IF(-SUM($D$20:H$20)>H19,H19,SUM($D$20:H$20)))) -> -13320000 | I21: =IF(IF(-SUM($D$20:I$20)>I19,I19,SUM($D$20:I$20))>=I19,0,(IF(-SUM($D$20:I$20)>I19,I19,SUM($D$20:I$20)))) -> -15984000 | J21: =IF(IF(-SUM($D$20:J$20)>J19,J19,SUM($D$20:J$20))>=J19,0,(IF(-SUM($D$20:J$20)>J19,J19,SUM($D$20:J$20)))) -> -18648000 | K21: =IF(IF(-SUM($D$20:K$20)>K19,K19,SUM($D$20:K$20))>=K19,0,(IF(-SUM($D$20:K$20)>K19,K19,SUM($D$20:K$20)))) -> -21312000 | ... BA21: =IF(IF(-SUM($D$20:BA$20)>BA19,BA19,SUM($D$20:BA$20))>=BA19,0,(IF(-SUM($D$20:BA$20)>BA19,BA19,SUM($D$20:BA$20)))) -> 0
B22: Återstående skuld vid årets slut | C22: → 5. IRR | D22: =IF(D$21>0,0,D$19+D$21) -> 86136000 | E22: =IF(E$21>0,0,E$19+E$21) -> 83472000 | F22: =IF(F$21>0,0,F$19+F$21) -> 80808000 | G22: =IF(G$21>0,0,G$19+G$21) -> 78144000 | H22: =IF(H$21>0,0,H$19+H$21) -> 75480000 | I22: =IF(I$21>0,0,I$19+I$21) -> 72816000 | J22: =IF(J$21>0,0,J$19+J$21) -> 70152000 | K22: =IF(K$21>0,0,K$19+K$21) -> 67488000 | ... BA22: =IF(BA$21>0,0,BA$19+BA$21) -> 88800000
B23: Räntesats (trappas upp år 1–11) | D23: ='3. Finansiering'!C7 -> 0.0307 | E23: =IF('3. Finansiering'!$C$7+(('3. Finansiering'!$C$8-'3. Finansiering'!$C$7)*(D14/$M$14))>'3. Finansiering'!$C$8,'3. Finansiering'!$C$8,('3. Finansiering'!$C$7+(('3. Finansiering'!$C$8-'3. Finansiering'!$C$7)*(D14/$M$14)))) -> 0.03218 | F23: =IF('3. Finansiering'!$C$7+(('3. Finansiering'!$C$8-'3. Finansiering'!$C$7)*(E14/$M$14))>'3. Finansiering'!$C$8,'3. Finansiering'!$C$8,('3. Finansiering'!$C$7+(('3. Finansiering'!$C$8-'3. Finansiering'!$C$7)*(E14/$M$14)))) -> 0.03366 | G23: =IF('3. Finansiering'!$C$7+(('3. Finansiering'!$C$8-'3. Finansiering'!$C$7)*(F14/$M$14))>'3. Finansiering'!$C$8,'3. Finansiering'!$C$8,('3. Finansiering'!$C$7+(('3. Finansiering'!$C$8-'3. Finansiering'!$C$7)*(F14/$M$14)))) -> 0.03514 | H23: =IF('3. Finansiering'!$C$7+(('3. Finansiering'!$C$8-'3. Finansiering'!$C$7)*(G14/$M$14))>'3. Finansiering'!$C$8,'3. Finansiering'!$C$8,('3. Finansiering'!$C$7+(('3. Finansiering'!$C$8-'3. Finansiering'!$C$7)*(G14/$M$14)))) -> 0.03662 | I23: =IF('3. Finansiering'!$C$7+(('3. Finansiering'!$C$8-'3. Finansiering'!$C$7)*(H14/$M$14))>'3. Finansiering'!$C$8,'3. Finansiering'!$C$8,('3. Finansiering'!$C$7+(('3. Finansiering'!$C$8-'3. Finansiering'!$C$7)*(H14/$M$14)))) -> 0.0381 | J23: =IF('3. Finansiering'!$C$7+(('3. Finansiering'!$C$8-'3. Finansiering'!$C$7)*(I14/$M$14))>'3. Finansiering'!$C$8,'3. Finansiering'!$C$8,('3. Finansiering'!$C$7+(('3. Finansiering'!$C$8-'3. Finansiering'!$C$7)*(I14/$M$14)))) -> 0.03958 | K23: =IF('3. Finansiering'!$C$7+(('3. Finansiering'!$C$8-'3. Finansiering'!$C$7)*(J14/$M$14))>'3. Finansiering'!$C$8,'3. Finansiering'!$C$8,('3. Finansiering'!$C$7+(('3. Finansiering'!$C$8-'3. Finansiering'!$C$7)*(J14/$M$14)))) -> 0.04106 | L23: =IF('3. Finansiering'!$C$7+(('3. Finansiering'!$C$8-'3. Finansiering'!$C$7)*(K14/$M$14))>'3. Finansiering'!$C$8,'3. Finansiering'!$C$8,('3. Finansiering'!$C$7+(('3. Finansiering'!$C$8-'3. Finansiering'!$C$7)*(K14/$M$14)))) -> 0.04254 | ... BA23: =IF('3. Finansiering'!$C$7+(('3. Finansiering'!$C$8-'3. Finansiering'!$C$7)*(AZ14/$M$14))>'3. Finansiering'!$C$8,'3. Finansiering'!$C$8,('3. Finansiering'!$C$7+(('3. Finansiering'!$C$8-'3. Finansiering'!$C$7)*(AZ14/$M$14)))) -> 0.0455
B24: Räntekostnad | C24: → 5. IRR | D24: =-D23*D22 -> -2644375.2 | E24: =-E23*E22 -> -2686129 | F24: =-F23*F22 -> -2719997.3 | G24: =-G23*G22 -> -2745980.2 | H24: =-H23*H22 -> -2764077.6 | I24: =-I23*I22 -> -2774289.6 | J24: =-J23*J22 -> -2776616.2 | K24: =-K23*K22 -> -2771057.3 | ... BA24: =-BA23*BA22 -> -4040400
B26: Finansieringskostnad (ränta + amortering) | D26: =IF(D24=0,0,D24+D20) -> -5308375.2 | E26: =IF(E24=0,0,E24+E20) -> -5350129 | F26: =IF(F24=0,0,F24+F20) -> -5383997.3 | G26: =IF(G24=0,0,G24+G20) -> -5409980.2 | H26: =IF(H24=0,0,H24+H20) -> -5428077.6 | I26: =IF(I24=0,0,I24+I20) -> -5438289.6 | J26: =IF(J24=0,0,J24+J20) -> -5440616.2 | K26: =IF(K24=0,0,K24+K20) -> -5435057.3 | ... BA26: =IF(BA24=0,0,BA24+BA20) -> -6704400
B27: Belåningsgrad vid årets slut | C27: → 7.Grafer | D27: =D22/(ABS(SUM($D$15:D$15))) -> 0.3589 | E27: =E22/(ABS(SUM($D$15:E$15))) -> 0.3478 | F27: =F22/(ABS(SUM($D$15:F$15))) -> 0.3367 | G27: =G22/(ABS(SUM($D$15:G$15))) -> 0.3256 | H27: =H22/(ABS(SUM($D$15:H$15))) -> 0.3145 | I27: =I22/(ABS(SUM($D$15:I$15))) -> 0.3034 | J27: =J22/(ABS(SUM($D$15:J$15))) -> 0.2923 | K27: =K22/(ABS(SUM($D$15:K$15))) -> 0.2812 | ... BA27: =BA22/(ABS(SUM($D$15:BA$15))) -> 0.37
B29: BOKFÖRT VÄRDE | C29: Högsta värde | D29: =IF(D14<='2. Kalkyldata'!$P$16,'3. Finansiering'!D13,"") -> 2026 | E29: =IF(E14<='2. Kalkyldata'!$P$16,'3. Finansiering'!E13,"") -> 2027 | F29: =IF(F14<='2. Kalkyldata'!$P$16,'3. Finansiering'!F13,"") -> 2028 | G29: =IF(G14<='2. Kalkyldata'!$P$16,'3. Finansiering'!G13,"") -> 2029 | H29: =IF(H14<='2. Kalkyldata'!$P$16,'3. Finansiering'!H13,"") -> 2030 | I29: =IF(I14<='2. Kalkyldata'!$P$16,'3. Finansiering'!I13,"") -> 2031 | J29: =IF(J14<='2. Kalkyldata'!$P$16,'3. Finansiering'!J13,"") -> 2032 | K29: =IF(K14<='2. Kalkyldata'!$P$16,'3. Finansiering'!K13,"") -> 2033 | ... BA29: =IF(BA14<='2. Kalkyldata'!$P$16,'3. Finansiering'!BA13,"") | BB29: =IF(BB13>=BB13+'2. Kalkyldata'!$P$16,"",'3. Finansiering'!BB13) -> 0
B30: Befintligt bokfört värde | D30: =IF(D$29="",0,('2. Kalkyldata'!$P$9-SUMIF('2. Kalkyldata'!$R$23:$R$27,'3. Finansiering'!D$12,'2. Kalkyldata'!$AA$23:$AA$27))) -> 0 | E30: =IF(E$29="",0,('2. Kalkyldata'!$P$9-SUMIF('2. Kalkyldata'!$R$23:$R$27,'3. Finansiering'!E$12,'2. Kalkyldata'!$AA$23:$AA$27))) -> 0 | F30: =IF(F$29="",0,('2. Kalkyldata'!$P$9-SUMIF('2. Kalkyldata'!$R$23:$R$27,'3. Finansiering'!F$12,'2. Kalkyldata'!$AA$23:$AA$27))) -> 0 | G30: =IF(G$29="",0,('2. Kalkyldata'!$P$9-SUMIF('2. Kalkyldata'!$R$23:$R$27,'3. Finansiering'!G$12,'2. Kalkyldata'!$AA$23:$AA$27))) -> 0 | H30: =IF(H$29="",0,('2. Kalkyldata'!$P$9-SUMIF('2. Kalkyldata'!$R$23:$R$27,'3. Finansiering'!H$12,'2. Kalkyldata'!$AA$23:$AA$27))) -> 0 | I30: =IF(I$29="",0,('2. Kalkyldata'!$P$9-SUMIF('2. Kalkyldata'!$R$23:$R$27,'3. Finansiering'!I$12,'2. Kalkyldata'!$AA$23:$AA$27))) -> 0 | J30: =IF(J$29="",0,('2. Kalkyldata'!$P$9-SUMIF('2. Kalkyldata'!$R$23:$R$27,'3. Finansiering'!J$12,'2. Kalkyldata'!$AA$23:$AA$27))) -> 0 | K30: =IF(K$29="",0,('2. Kalkyldata'!$P$9-SUMIF('2. Kalkyldata'!$R$23:$R$27,'3. Finansiering'!K$12,'2. Kalkyldata'!$AA$23:$AA$27))) -> 0 | ... BA30: =IF(BA$29="",0,('2. Kalkyldata'!$P$9-SUMIF('2. Kalkyldata'!$R$23:$R$27,'3. Finansiering'!BA$12,'2. Kalkyldata'!$AA$23:$AA$27))) -> 0
B31: ='2. Kalkyldata'!C23 -> Skola | D31: =IF(D$29="",0,SUMIFS('2. Kalkyldata'!$W$23:$W$27,'2. Kalkyldata'!$C$23:$C$27,'3. Finansiering'!$B31,'2. Kalkyldata'!$R$23:$R$27,'3. Finansiering'!D$12)) -> 2.4e+08 | E31: =IF(E$29="",0,SUMIFS('2. Kalkyldata'!$W$23:$W$27,'2. Kalkyldata'!$C$23:$C$27,'3. Finansiering'!$B31,'2. Kalkyldata'!$R$23:$R$27,'3. Finansiering'!E$12)) -> 2.4e+08 | F31: =IF(F$29="",0,SUMIFS('2. Kalkyldata'!$W$23:$W$27,'2. Kalkyldata'!$C$23:$C$27,'3. Finansiering'!$B31,'2. Kalkyldata'!$R$23:$R$27,'3. Finansiering'!F$12)) -> 2.4e+08 | G31: =IF(G$29="",0,SUMIFS('2. Kalkyldata'!$W$23:$W$27,'2. Kalkyldata'!$C$23:$C$27,'3. Finansiering'!$B31,'2. Kalkyldata'!$R$23:$R$27,'3. Finansiering'!G$12)) -> 2.4e+08 | H31: =IF(H$29="",0,SUMIFS('2. Kalkyldata'!$W$23:$W$27,'2. Kalkyldata'!$C$23:$C$27,'3. Finansiering'!$B31,'2. Kalkyldata'!$R$23:$R$27,'3. Finansiering'!H$12)) -> 2.4e+08 | I31: =IF(I$29="",0,SUMIFS('2. Kalkyldata'!$W$23:$W$27,'2. Kalkyldata'!$C$23:$C$27,'3. Finansiering'!$B31,'2. Kalkyldata'!$R$23:$R$27,'3. Finansiering'!I$12)) -> 2.4e+08 | J31: =IF(J$29="",0,SUMIFS('2. Kalkyldata'!$W$23:$W$27,'2. Kalkyldata'!$C$23:$C$27,'3. Finansiering'!$B31,'2. Kalkyldata'!$R$23:$R$27,'3. Finansiering'!J$12)) -> 2.4e+08 | K31: =IF(K$29="",0,SUMIFS('2. Kalkyldata'!$W$23:$W$27,'2. Kalkyldata'!$C$23:$C$27,'3. Finansiering'!$B31,'2. Kalkyldata'!$R$23:$R$27,'3. Finansiering'!K$12)) -> 2.4e+08 | ... BA31: =IF(BA$29="",0,SUMIFS('2. Kalkyldata'!$W$23:$W$27,'2. Kalkyldata'!$C$23:$C$27,'3. Finansiering'!$B31,'2. Kalkyldata'!$R$23:$R$27,'3. Finansiering'!BA$12)) -> 0
B32: ='2. Kalkyldata'!C24 -> 0 | D32: =IF(D$29="",0,SUMIFS('2. Kalkyldata'!$W$23:$W$27,'2. Kalkyldata'!$C$23:$C$27,'3. Finansiering'!$B32,'2. Kalkyldata'!$R$23:$R$27,'3. Finansiering'!D$12)) -> 0 | E32: =IF(E$29="",0,SUMIFS('2. Kalkyldata'!$W$23:$W$27,'2. Kalkyldata'!$C$23:$C$27,'3. Finansiering'!$B32,'2. Kalkyldata'!$R$23:$R$27,'3. Finansiering'!E$12)) -> 0 | F32: =IF(F$29="",0,SUMIFS('2. Kalkyldata'!$W$23:$W$27,'2. Kalkyldata'!$C$23:$C$27,'3. Finansiering'!$B32,'2. Kalkyldata'!$R$23:$R$27,'3. Finansiering'!F$12)) -> 0 | G32: =IF(G$29="",0,SUMIFS('2. Kalkyldata'!$W$23:$W$27,'2. Kalkyldata'!$C$23:$C$27,'3. Finansiering'!$B32,'2. Kalkyldata'!$R$23:$R$27,'3. Finansiering'!G$12)) -> 0 | H32: =IF(H$29="",0,SUMIFS('2. Kalkyldata'!$W$23:$W$27,'2. Kalkyldata'!$C$23:$C$27,'3. Finansiering'!$B32,'2. Kalkyldata'!$R$23:$R$27,'3. Finansiering'!H$12)) -> 0 | I32: =IF(I$29="",0,SUMIFS('2. Kalkyldata'!$W$23:$W$27,'2. Kalkyldata'!$C$23:$C$27,'3. Finansiering'!$B32,'2. Kalkyldata'!$R$23:$R$27,'3. Finansiering'!I$12)) -> 0 | J32: =IF(J$29="",0,SUMIFS('2. Kalkyldata'!$W$23:$W$27,'2. Kalkyldata'!$C$23:$C$27,'3. Finansiering'!$B32,'2. Kalkyldata'!$R$23:$R$27,'3. Finansiering'!J$12)) -> 0 | K32: =IF(K$29="",0,SUMIFS('2. Kalkyldata'!$W$23:$W$27,'2. Kalkyldata'!$C$23:$C$27,'3. Finansiering'!$B32,'2. Kalkyldata'!$R$23:$R$27,'3. Finansiering'!K$12)) -> 0 | ... BA32: =IF(BA$29="",0,SUMIFS('2. Kalkyldata'!$W$23:$W$27,'2. Kalkyldata'!$C$23:$C$27,'3. Finansiering'!$B32,'2. Kalkyldata'!$R$23:$R$27,'3. Finansiering'!BA$12)) -> 0
B33: ='2. Kalkyldata'!C25 -> 0 | D33: =IF(D$29="",0,SUMIFS('2. Kalkyldata'!$W$23:$W$27,'2. Kalkyldata'!$C$23:$C$27,'3. Finansiering'!$B33,'2. Kalkyldata'!$R$23:$R$27,'3. Finansiering'!D$12)) -> 0 | E33: =IF(E$29="",0,SUMIFS('2. Kalkyldata'!$W$23:$W$27,'2. Kalkyldata'!$C$23:$C$27,'3. Finansiering'!$B33,'2. Kalkyldata'!$R$23:$R$27,'3. Finansiering'!E$12)) -> 0 | F33: =IF(F$29="",0,SUMIFS('2. Kalkyldata'!$W$23:$W$27,'2. Kalkyldata'!$C$23:$C$27,'3. Finansiering'!$B33,'2. Kalkyldata'!$R$23:$R$27,'3. Finansiering'!F$12)) -> 0 | G33: =IF(G$29="",0,SUMIFS('2. Kalkyldata'!$W$23:$W$27,'2. Kalkyldata'!$C$23:$C$27,'3. Finansiering'!$B33,'2. Kalkyldata'!$R$23:$R$27,'3. Finansiering'!G$12)) -> 0 | H33: =IF(H$29="",0,SUMIFS('2. Kalkyldata'!$W$23:$W$27,'2. Kalkyldata'!$C$23:$C$27,'3. Finansiering'!$B33,'2. Kalkyldata'!$R$23:$R$27,'3. Finansiering'!H$12)) -> 0 | I33: =IF(I$29="",0,SUMIFS('2. Kalkyldata'!$W$23:$W$27,'2. Kalkyldata'!$C$23:$C$27,'3. Finansiering'!$B33,'2. Kalkyldata'!$R$23:$R$27,'3. Finansiering'!I$12)) -> 0 | J33: =IF(J$29="",0,SUMIFS('2. Kalkyldata'!$W$23:$W$27,'2. Kalkyldata'!$C$23:$C$27,'3. Finansiering'!$B33,'2. Kalkyldata'!$R$23:$R$27,'3. Finansiering'!J$12)) -> 0 | K33: =IF(K$29="",0,SUMIFS('2. Kalkyldata'!$W$23:$W$27,'2. Kalkyldata'!$C$23:$C$27,'3. Finansiering'!$B33,'2. Kalkyldata'!$R$23:$R$27,'3. Finansiering'!K$12)) -> 0 | ... BA33: =IF(BA$29="",0,SUMIFS('2. Kalkyldata'!$W$23:$W$27,'2. Kalkyldata'!$C$23:$C$27,'3. Finansiering'!$B33,'2. Kalkyldata'!$R$23:$R$27,'3. Finansiering'!BA$12)) -> 0
B34: ='2. Kalkyldata'!C26 -> 0 | D34: =IF(D$29="",0,SUMIFS('2. Kalkyldata'!$W$23:$W$27,'2. Kalkyldata'!$C$23:$C$27,'3. Finansiering'!$B34,'2. Kalkyldata'!$R$23:$R$27,'3. Finansiering'!D$12)) -> 0 | E34: =IF(E$29="",0,SUMIFS('2. Kalkyldata'!$W$23:$W$27,'2. Kalkyldata'!$C$23:$C$27,'3. Finansiering'!$B34,'2. Kalkyldata'!$R$23:$R$27,'3. Finansiering'!E$12)) -> 0 | F34: =IF(F$29="",0,SUMIFS('2. Kalkyldata'!$W$23:$W$27,'2. Kalkyldata'!$C$23:$C$27,'3. Finansiering'!$B34,'2. Kalkyldata'!$R$23:$R$27,'3. Finansiering'!F$12)) -> 0 | G34: =IF(G$29="",0,SUMIFS('2. Kalkyldata'!$W$23:$W$27,'2. Kalkyldata'!$C$23:$C$27,'3. Finansiering'!$B34,'2. Kalkyldata'!$R$23:$R$27,'3. Finansiering'!G$12)) -> 0 | H34: =IF(H$29="",0,SUMIFS('2. Kalkyldata'!$W$23:$W$27,'2. Kalkyldata'!$C$23:$C$27,'3. Finansiering'!$B34,'2. Kalkyldata'!$R$23:$R$27,'3. Finansiering'!H$12)) -> 0 | I34: =IF(I$29="",0,SUMIFS('2. Kalkyldata'!$W$23:$W$27,'2. Kalkyldata'!$C$23:$C$27,'3. Finansiering'!$B34,'2. Kalkyldata'!$R$23:$R$27,'3. Finansiering'!I$12)) -> 0 | J34: =IF(J$29="",0,SUMIFS('2. Kalkyldata'!$W$23:$W$27,'2. Kalkyldata'!$C$23:$C$27,'3. Finansiering'!$B34,'2. Kalkyldata'!$R$23:$R$27,'3. Finansiering'!J$12)) -> 0 | K34: =IF(K$29="",0,SUMIFS('2. Kalkyldata'!$W$23:$W$27,'2. Kalkyldata'!$C$23:$C$27,'3. Finansiering'!$B34,'2. Kalkyldata'!$R$23:$R$27,'3. Finansiering'!K$12)) -> 0 | ... BA34: =IF(BA$29="",0,SUMIFS('2. Kalkyldata'!$W$23:$W$27,'2. Kalkyldata'!$C$23:$C$27,'3. Finansiering'!$B34,'2. Kalkyldata'!$R$23:$R$27,'3. Finansiering'!BA$12)) -> 0
B35: ='2. Kalkyldata'!C27 -> 0 | D35: =IF(D$29="",0,SUMIFS('2. Kalkyldata'!$W$23:$W$27,'2. Kalkyldata'!$C$23:$C$27,'3. Finansiering'!$B35,'2. Kalkyldata'!$R$23:$R$27,'3. Finansiering'!D$12)) -> 0 | E35: =IF(E$29="",0,SUMIFS('2. Kalkyldata'!$W$23:$W$27,'2. Kalkyldata'!$C$23:$C$27,'3. Finansiering'!$B35,'2. Kalkyldata'!$R$23:$R$27,'3. Finansiering'!E$12)) -> 0 | F35: =IF(F$29="",0,SUMIFS('2. Kalkyldata'!$W$23:$W$27,'2. Kalkyldata'!$C$23:$C$27,'3. Finansiering'!$B35,'2. Kalkyldata'!$R$23:$R$27,'3. Finansiering'!F$12)) -> 0 | G35: =IF(G$29="",0,SUMIFS('2. Kalkyldata'!$W$23:$W$27,'2. Kalkyldata'!$C$23:$C$27,'3. Finansiering'!$B35,'2. Kalkyldata'!$R$23:$R$27,'3. Finansiering'!G$12)) -> 0 | H35: =IF(H$29="",0,SUMIFS('2. Kalkyldata'!$W$23:$W$27,'2. Kalkyldata'!$C$23:$C$27,'3. Finansiering'!$B35,'2. Kalkyldata'!$R$23:$R$27,'3. Finansiering'!H$12)) -> 0 | I35: =IF(I$29="",0,SUMIFS('2. Kalkyldata'!$W$23:$W$27,'2. Kalkyldata'!$C$23:$C$27,'3. Finansiering'!$B35,'2. Kalkyldata'!$R$23:$R$27,'3. Finansiering'!I$12)) -> 0 | J35: =IF(J$29="",0,SUMIFS('2. Kalkyldata'!$W$23:$W$27,'2. Kalkyldata'!$C$23:$C$27,'3. Finansiering'!$B35,'2. Kalkyldata'!$R$23:$R$27,'3. Finansiering'!J$12)) -> 0 | K35: =IF(K$29="",0,SUMIFS('2. Kalkyldata'!$W$23:$W$27,'2. Kalkyldata'!$C$23:$C$27,'3. Finansiering'!$B35,'2. Kalkyldata'!$R$23:$R$27,'3. Finansiering'!K$12)) -> 0 | ... BA35: =IF(BA$29="",0,SUMIFS('2. Kalkyldata'!$W$23:$W$27,'2. Kalkyldata'!$C$23:$C$27,'3. Finansiering'!$B35,'2. Kalkyldata'!$R$23:$R$27,'3. Finansiering'!BA$12)) -> 0
B36: Residual | D36: =IF(D$29="",0,SUMIFS('2. Kalkyldata'!$W$23:$W$27,'2. Kalkyldata'!$C$23:$C$27,'3. Finansiering'!$B36,'2. Kalkyldata'!$R$23:$R$27,'3. Finansiering'!D$12)) -> 0 | E36: =IF(E$29="",0,SUMIFS('2. Kalkyldata'!$W$23:$W$27,'2. Kalkyldata'!$C$23:$C$27,'3. Finansiering'!$B36,'2. Kalkyldata'!$R$23:$R$27,'3. Finansiering'!E$12)) -> 0 | F36: =IF(F$29="",0,SUMIFS('2. Kalkyldata'!$W$23:$W$27,'2. Kalkyldata'!$C$23:$C$27,'3. Finansiering'!$B36,'2. Kalkyldata'!$R$23:$R$27,'3. Finansiering'!F$12)) -> 0 | G36: =IF(G$29="",0,SUMIFS('2. Kalkyldata'!$W$23:$W$27,'2. Kalkyldata'!$C$23:$C$27,'3. Finansiering'!$B36,'2. Kalkyldata'!$R$23:$R$27,'3. Finansiering'!G$12)) -> 0 | H36: =IF(H$29="",0,SUMIFS('2. Kalkyldata'!$W$23:$W$27,'2. Kalkyldata'!$C$23:$C$27,'3. Finansiering'!$B36,'2. Kalkyldata'!$R$23:$R$27,'3. Finansiering'!H$12)) -> 0 | I36: =IF(I$29="",0,SUMIFS('2. Kalkyldata'!$W$23:$W$27,'2. Kalkyldata'!$C$23:$C$27,'3. Finansiering'!$B36,'2. Kalkyldata'!$R$23:$R$27,'3. Finansiering'!I$12)) -> 0 | J36: =IF(J$29="",0,SUMIFS('2. Kalkyldata'!$W$23:$W$27,'2. Kalkyldata'!$C$23:$C$27,'3. Finansiering'!$B36,'2. Kalkyldata'!$R$23:$R$27,'3. Finansiering'!J$12)) -> 0 | K36: =IF(K$29="",0,SUMIFS('2. Kalkyldata'!$W$23:$W$27,'2. Kalkyldata'!$C$23:$C$27,'3. Finansiering'!$B36,'2. Kalkyldata'!$R$23:$R$27,'3. Finansiering'!K$12)) -> 0 | ... BA36: =IF(BA$29="",0,SUMIFS('2. Kalkyldata'!$W$23:$W$27,'2. Kalkyldata'!$C$23:$C$27,'3. Finansiering'!$B36,'2. Kalkyldata'!$R$23:$R$27,'3. Finansiering'!BA$12)) -> 0
B37: ='2. Kalkyldata'!C28 -> Totalt | C37: =MAX($D$37:$BA$37) -> 2.4e+08 | D37: =SUM(D30:D35) -> 2.4e+08 | E37: =SUM(E30:E35) -> 2.4e+08 | F37: =SUM(F30:F35) -> 2.4e+08 | G37: =SUM(G30:G35) -> 2.4e+08 | H37: =SUM(H30:H35) -> 2.4e+08 | I37: =SUM(I30:I35) -> 2.4e+08 | J37: =SUM(J30:J35) -> 2.4e+08 | K37: =SUM(K30:K35) -> 2.4e+08 | ... BA37: =SUM(BA30:BA35) -> 0
B39: AVSKRIVNING | C39: Rak avskrivning; avskrivningstider enligt 2. Kalkyldata P13/P16. Per objekt i grupperade rader 40–46.
B40: Befintligt bokfört värde | D40: =-D30/'2. Kalkyldata'!$P$13 -> 0 | E40: =-E30/'2. Kalkyldata'!$P$13 -> 0 | F40: =-F30/'2. Kalkyldata'!$P$13 -> 0 | G40: =-G30/'2. Kalkyldata'!$P$13 -> 0 | H40: =-H30/'2. Kalkyldata'!$P$13 -> 0 | I40: =-I30/'2. Kalkyldata'!$P$13 -> 0 | J40: =-J30/'2. Kalkyldata'!$P$13 -> 0 | K40: =-K30/'2. Kalkyldata'!$P$13 -> 0 | ... BA40: =-BA30/'2. Kalkyldata'!$P$13 -> 0
B41: =B31 -> Skola | D41: =IF(D$29<'2. Kalkyldata'!$M23,0,-D31/'2. Kalkyldata'!$P$16) -> -7272727.3 | E41: =IF(E$29<'2. Kalkyldata'!$M23,0,-E31/'2. Kalkyldata'!$P$16) -> -7272727.3 | F41: =IF(F$29<'2. Kalkyldata'!$M23,0,-F31/'2. Kalkyldata'!$P$16) -> -7272727.3 | G41: =IF(G$29<'2. Kalkyldata'!$M23,0,-G31/'2. Kalkyldata'!$P$16) -> -7272727.3 | H41: =IF(H$29<'2. Kalkyldata'!$M23,0,-H31/'2. Kalkyldata'!$P$16) -> -7272727.3 | I41: =IF(I$29<'2. Kalkyldata'!$M23,0,-I31/'2. Kalkyldata'!$P$16) -> -7272727.3 | J41: =IF(J$29<'2. Kalkyldata'!$M23,0,-J31/'2. Kalkyldata'!$P$16) -> -7272727.3 | K41: =IF(K$29<'2. Kalkyldata'!$M23,0,-K31/'2. Kalkyldata'!$P$16) -> -7272727.3 | ... BA41: =IF(BA$29<'2. Kalkyldata'!$M23,0,-BA31/'2. Kalkyldata'!$P$16) -> 0
B42: =B32 -> 0 | D42: =IF(D$29<'2. Kalkyldata'!$M24,0,-D32/'2. Kalkyldata'!$P$16) -> 0 | E42: =IF(E$29<'2. Kalkyldata'!$M24,0,-E32/'2. Kalkyldata'!$P$16) -> 0 | F42: =IF(F$29<'2. Kalkyldata'!$M24,0,-F32/'2. Kalkyldata'!$P$16) -> 0 | G42: =IF(G$29<'2. Kalkyldata'!$M24,0,-G32/'2. Kalkyldata'!$P$16) -> 0 | H42: =IF(H$29<'2. Kalkyldata'!$M24,0,-H32/'2. Kalkyldata'!$P$16) -> 0 | I42: =IF(I$29<'2. Kalkyldata'!$M24,0,-I32/'2. Kalkyldata'!$P$16) -> 0 | J42: =IF(J$29<'2. Kalkyldata'!$M24,0,-J32/'2. Kalkyldata'!$P$16) -> 0 | K42: =IF(K$29<'2. Kalkyldata'!$M24,0,-K32/'2. Kalkyldata'!$P$16) -> 0 | ... BA42: =IF(BA$29<'2. Kalkyldata'!$M24,0,-BA32/'2. Kalkyldata'!$P$16) -> 0
B43: =B33 -> 0 | D43: =IF(D$29<'2. Kalkyldata'!$M25,0,-D33/'2. Kalkyldata'!$P$16) -> 0 | E43: =IF(E$29<'2. Kalkyldata'!$M25,0,-E33/'2. Kalkyldata'!$P$16) -> 0 | F43: =IF(F$29<'2. Kalkyldata'!$M25,0,-F33/'2. Kalkyldata'!$P$16) -> 0 | G43: =IF(G$29<'2. Kalkyldata'!$M25,0,-G33/'2. Kalkyldata'!$P$16) -> 0 | H43: =IF(H$29<'2. Kalkyldata'!$M25,0,-H33/'2. Kalkyldata'!$P$16) -> 0 | I43: =IF(I$29<'2. Kalkyldata'!$M25,0,-I33/'2. Kalkyldata'!$P$16) -> 0 | J43: =IF(J$29<'2. Kalkyldata'!$M25,0,-J33/'2. Kalkyldata'!$P$16) -> 0 | K43: =IF(K$29<'2. Kalkyldata'!$M25,0,-K33/'2. Kalkyldata'!$P$16) -> 0 | ... BA43: =IF(BA$29<'2. Kalkyldata'!$M25,0,-BA33/'2. Kalkyldata'!$P$16) -> 0
B44: =B34 -> 0 | D44: =IF(D$29<'2. Kalkyldata'!$M26,0,-D34/'2. Kalkyldata'!$P$16) -> 0 | E44: =IF(E$29<'2. Kalkyldata'!$M26,0,-E34/'2. Kalkyldata'!$P$16) -> 0 | F44: =IF(F$29<'2. Kalkyldata'!$M26,0,-F34/'2. Kalkyldata'!$P$16) -> 0 | G44: =IF(G$29<'2. Kalkyldata'!$M26,0,-G34/'2. Kalkyldata'!$P$16) -> 0 | H44: =IF(H$29<'2. Kalkyldata'!$M26,0,-H34/'2. Kalkyldata'!$P$16) -> 0 | I44: =IF(I$29<'2. Kalkyldata'!$M26,0,-I34/'2. Kalkyldata'!$P$16) -> 0 | J44: =IF(J$29<'2. Kalkyldata'!$M26,0,-J34/'2. Kalkyldata'!$P$16) -> 0 | K44: =IF(K$29<'2. Kalkyldata'!$M26,0,-K34/'2. Kalkyldata'!$P$16) -> 0 | ... BA44: =IF(BA$29<'2. Kalkyldata'!$M26,0,-BA34/'2. Kalkyldata'!$P$16) -> 0
B45: =B35 -> 0 | D45: =IF(D$29<'2. Kalkyldata'!$M27,0,-D35/'2. Kalkyldata'!$P$16) -> 0 | E45: =IF(E$29<'2. Kalkyldata'!$M27,0,-E35/'2. Kalkyldata'!$P$16) -> 0 | F45: =IF(F$29<'2. Kalkyldata'!$M27,0,-F35/'2. Kalkyldata'!$P$16) -> 0 | G45: =IF(G$29<'2. Kalkyldata'!$M27,0,-G35/'2. Kalkyldata'!$P$16) -> 0 | H45: =IF(H$29<'2. Kalkyldata'!$M27,0,-H35/'2. Kalkyldata'!$P$16) -> 0 | I45: =IF(I$29<'2. Kalkyldata'!$M27,0,-I35/'2. Kalkyldata'!$P$16) -> 0 | J45: =IF(J$29<'2. Kalkyldata'!$M27,0,-J35/'2. Kalkyldata'!$P$16) -> 0 | K45: =IF(K$29<'2. Kalkyldata'!$M27,0,-K35/'2. Kalkyldata'!$P$16) -> 0 | ... BA45: =IF(BA$29<'2. Kalkyldata'!$M27,0,-BA35/'2. Kalkyldata'!$P$16) -> 0
B46: Residual | D46: =IF(D$29<'2. Kalkyldata'!$M28,0,-D36/'2. Kalkyldata'!$P$16) -> 0 | E46: =IF(E$29<'2. Kalkyldata'!$M28,0,-E36/'2. Kalkyldata'!$P$16) -> 0 | F46: =IF(F$29<'2. Kalkyldata'!$M28,0,-F36/'2. Kalkyldata'!$P$16) -> 0 | G46: =IF(G$29<'2. Kalkyldata'!$M28,0,-G36/'2. Kalkyldata'!$P$16) -> 0 | H46: =IF(H$29<'2. Kalkyldata'!$M28,0,-H36/'2. Kalkyldata'!$P$16) -> 0 | I46: =IF(I$29<'2. Kalkyldata'!$M28,0,-I36/'2. Kalkyldata'!$P$16) -> 0 | J46: =IF(J$29<'2. Kalkyldata'!$M28,0,-J36/'2. Kalkyldata'!$P$16) -> 0 | K46: =IF(K$29<'2. Kalkyldata'!$M28,0,-K36/'2. Kalkyldata'!$P$16) -> 0 | ... BA46: =IF(BA$29<'2. Kalkyldata'!$M28,0,-BA36/'2. Kalkyldata'!$P$16) -> 0
B47: Årets avskrivning | C47: → 5. IRR | D47: =SUM(D40:D46) -> -7272727.3 | E47: =SUM(E40:E46) -> -7272727.3 | F47: =SUM(F40:F46) -> -7272727.3 | G47: =SUM(G40:G46) -> -7272727.3 | H47: =SUM(H40:H46) -> -7272727.3 | I47: =SUM(I40:I46) -> -7272727.3 | J47: =SUM(J40:J46) -> -7272727.3 | K47: =SUM(K40:K46) -> -7272727.3 | ... BA47: =SUM(BA40:BA46) -> 0
...

Sheet 4. NPV
B1: Nettonuvärde (NPV)
B2: Nettonuvärdet (NPV) är nuvärdet av investeringens framtida driftnetton under kalkylperioden plus restvärdet vid periodens slut, diskonterat med kalkylräntan, minus investeringen. Beslutet läses på rad 82: NPV tillkommande (krav 1, ska vara ≥ 0). Rad 47–62 visar hela fastigheten (krav 3) och rad 84–91 hur restvärdet räknas.
D3: =CONCATENATE("<=",D4) -> <=2026 | E3: =CONCATENATE("<=",E4) -> <=2027 | F3: =CONCATENATE("<=",F4) -> <=2028 | G3: =CONCATENATE("<=",G4) -> <=2029 | H3: =CONCATENATE("<=",H4) -> <=2030 | I3: =CONCATENATE("<=",I4) -> <=2031 | J3: =CONCATENATE("<=",J4) -> <=2032 | K3: =CONCATENATE("<=",K4) -> <=2033 | ... BA3: =CONCATENATE("<=",BA4) -> <=
D4: =_xlfn.NUMBERVALUE('3. Finansiering'!D$13) -> 2026 | E4: ='3. Finansiering'!E$13 -> 2027 | F4: ='3. Finansiering'!F$13 -> 2028 | G4: ='3. Finansiering'!G$13 -> 2029 | H4: ='3. Finansiering'!H$13 -> 2030 | I4: ='3. Finansiering'!I$13 -> 2031 | J4: ='3. Finansiering'!J$13 -> 2032 | K4: ='3. Finansiering'!K$13 -> 2033 | L4: ='3. Finansiering'!L$13 -> 2034 | ... BA4: ='3. Finansiering'!BA$13
B5: Kalkylår nr | D5: ='3. Finansiering'!D14 -> 1 | E5: ='3. Finansiering'!E14 -> 2 | F5: ='3. Finansiering'!F14 -> 3 | G5: ='3. Finansiering'!G14 -> 4 | H5: ='3. Finansiering'!H14 -> 5 | I5: ='3. Finansiering'!I14 -> 6 | J5: ='3. Finansiering'!J14 -> 7 | K5: ='3. Finansiering'!K14 -> 8 | ... BA5: ='3. Finansiering'!BA14 -> 50
B6: Area nybyggnad, kvm | D6: =SUMIFS('2. Kalkyldata'!$H$23:$H$27,'2. Kalkyldata'!$E$23:$E$27,"nyb",'2. Kalkyldata'!$M$23:$M$27,'4. NPV'!D3) -> 6100 | E6: =SUMIFS('2. Kalkyldata'!$H$23:$H$27,'2. Kalkyldata'!$E$23:$E$27,"nyb",'2. Kalkyldata'!$M$23:$M$27,'4. NPV'!E3) -> 6100 | F6: =SUMIFS('2. Kalkyldata'!$H$23:$H$27,'2. Kalkyldata'!$E$23:$E$27,"nyb",'2. Kalkyldata'!$M$23:$M$27,'4. NPV'!F3) -> 6100 | G6: =SUMIFS('2. Kalkyldata'!$H$23:$H$27,'2. Kalkyldata'!$E$23:$E$27,"nyb",'2. Kalkyldata'!$M$23:$M$27,'4. NPV'!G3) -> 6100 | H6: =SUMIFS('2. Kalkyldata'!$H$23:$H$27,'2. Kalkyldata'!$E$23:$E$27,"nyb",'2. Kalkyldata'!$M$23:$M$27,'4. NPV'!H3) -> 6100 | I6: =SUMIFS('2. Kalkyldata'!$H$23:$H$27,'2. Kalkyldata'!$E$23:$E$27,"nyb",'2. Kalkyldata'!$M$23:$M$27,'4. NPV'!I3) -> 6100 | J6: =SUMIFS('2. Kalkyldata'!$H$23:$H$27,'2. Kalkyldata'!$E$23:$E$27,"nyb",'2. Kalkyldata'!$M$23:$M$27,'4. NPV'!J3) -> 6100 | K6: =SUMIFS('2. Kalkyldata'!$H$23:$H$27,'2. Kalkyldata'!$E$23:$E$27,"nyb",'2. Kalkyldata'!$M$23:$M$27,'4. NPV'!K3) -> 6100 | ... BA6: =SUMIFS('2. Kalkyldata'!$H$23:$H$27,'2. Kalkyldata'!$E$23:$E$27,"nyb",'2. Kalkyldata'!$M$23:$M$27,'4. NPV'!BA3) -> 0
