Workbook

Sheet Översikt
A2: 'Försättsblad'!A1 | B2: LEJONFASTIGHETER · INVESTERINGSANALYS
B3: Investeringskalkyl
A4: 'Indata'!A1 | B4: =Indata!B26&" · Kalkylstart "&Indata!C5 -> Skola · Kalkylstart 2026
A5: 'Kassaflöde'!A1
A6: 'Finansiering'!A1
A7: 'Resultat'!A1 | B7: BINDANDE KRAVHYRA | E7: PER M² OCH ÅR | H7: FAKTISK IRR EK
A8: 'Grafer'!A1 | B8: =Resultat!D14 -> 11631222 | E8: =Resultat!D16 -> 2326.2443 | H8: =Lönsamhetskontroll!C45 -> 0.076451715
A9: 'Lönsamhetskontroll'!A1 | B9: kr/år · högsta av de tre lönsamhetskraven | E9: kr/m²/år (totalarea) | H9: =Lönsamhetskontroll!C47*100 -> 1.3451715 | J9: =Indata!C65 -> 0.063
A10: 'Beräkningslogik'!A1
A11: 'Dokumentation'!A1
B12: FÖRUTSÄTTNINGAR | E12: DRIFTNETTO ÅR FÖR ÅR | H12: LÖNSAMHETSKRAV
B13: Total investering | C13: =Indata!R31 -> 200000000 | E13: ="År 1 ("&Indata!C5&")" -> År 1 (2026) | F13: =Kassaflöde!D23 -> 9231221.7 | H13: 1. NPV ≥ 0 | J13: =Lönsamhetskontroll!D9 -> ✓ Uppfyllt
B14: Investering per m² | C14: =IFERROR(Indata!R31/Indata!F31,0) -> 40000 | E14: ="År "&Indata!C16&" ("&(Indata!C5+Indata!C16-1)&")" -> År 20 (2045) | F14: =INDEX(Kassaflöde!D23:AB23,MATCH(Indata!C16,Kassaflöde!D4:AB4,0)) -> 11651346 | H14: 2. IRR EK ≥ avkastningskrav | J14: =Lönsamhetskontroll!D45 -> ✓ Uppfyllt
B15: Verksamhetsyta | C15: =Indata!F31 -> 5000 | E15: Tillväxt över perioden | F15: =IFERROR(F14/F13-1,0) -> 0.26216724 | H15: 3. Marknadsvärde ≥ bokfört värde | J15: =Lönsamhetskontroll!D30 -> ✓ Uppfyllt
B16: Kalkylperiod | C16: =Indata!C16 -> 20
B17: Belåningsgrad | C17: =Indata!C64 -> 0.37 | E17: Driftnetto = nettohyra minus drift och underhåll. Hela projektionen finns på fliken Kassaflöde. | H17: Utvärderas vid bindande kravhyra och mål-utfall. Detaljer på fliken Lönsamhetskontroll.
B18: Avkastningskrav EK | C18: =Indata!C65 -> 0.063
B19: Kalkylränta driftnetto | C19: =Indata!C7 -> 0.04
B22: HYRESSPANN VID INVESTERINGSUTFALL | H22: ="Investeringsintervall ±"&Indata!C68*100&" %" -> Investeringsintervall ±10 %
B24: =Resultat!C14 -> 10726244 | E24: =Resultat!D14 -> 11631222 | H24: =Resultat!E14 -> 12536199
B25: ="Lägsta utfall (−"&Indata!C68*100&" %)" -> Lägsta utfall (−10 %) | E25: Mål-utfall (bindande kravhyra) | H25: ="Högsta utfall (+"&Indata!C68*100&" %)" -> Högsta utfall (+10 %)
B26: Avtalet bör ange hyresspannet. Slutlig hyra fastställs när investeringsutfallet är känt vid projektavslut.
B28: Lejonfastigheter AB · Investeringskalkyl · Beslutsunderlag

Sheet Försättsblad
B2: LEJONFASTIGHETER · INVESTERINGSMEMO
A3: 'Översikt'!A1
A4: 'Indata'!A1 | B4: Investeringskalkyl
A5: 'Kassaflöde'!A1 | B5: =IF(Indata!B26="","(projekt ej namngivet)",Indata!B26&" · "&IF(Indata!C26="Nyb","Nybyggnad",IF(Indata!C26="Omb","Ombyggnad","Befintligt"))) -> Skola · Nybyggnad
A6: 'Finansiering'!A1
A7: 'Resultat'!A1 | B7: PROJEKTINFORMATION
A8: 'Grafer'!A1 | B8: Projektnamn | C8: =Indata!B26 -> Skola | G8: Kalkylstart | H8: =Indata!C5 -> 2026
A9: 'Lönsamhetskontroll'!A1 | B9: Fastighet | C9: Fyll i | G9: Kalkylperiod | H9: =Indata!C16 -> 20
A10: 'Beräkningslogik'!A1 | B10: Objekt | C10: Fyll i | G10: Total investering | H10: =Indata!R31 -> 200000000
A11: 'Dokumentation'!A1 | B11: Projektnummer | C11: Fyll i | G11: Verksamhetsyta | H11: =Indata!F31 -> 5000
B12: Kalkyl utförd av | C12: Fyll i | G12: Typ av projekt | H12: =IF(Indata!C26="Nyb","Nybyggnad",IF(Indata!C26="Omb","Ombyggnad","Befintligt")) -> Nybyggnad
B13: Momsregistrering före | C13: =Indata!C12 -> 1 | G13: Momsregistrering efter | H13: =Indata!C13 -> 1
B15: PROJEKTBESKRIVNING
B16: Åtgärd | C16: kvm (BRA) | D16: Inv belopp | E16: kr/kvm
B17: Befintligt | C17: Fyll i | D17: Fyll i | E17: Fyll i
B18: Ombyggnad | C18: Fyll i | D18: Fyll i | E18: Fyll i
B19: Nybyggnad | C19: =Indata!F31 -> 5000 | D19: =Indata!R31 -> 200000000 | E19: =IFERROR(Indata!R31/Indata!F31,0) -> 40000
B20: Installationer | C20: Fyll i | D20: Fyll i | E20: Fyll i
B21: Mark | C21: =Indata!C20 -> 10000 | D21: =Indata!C20*Indata!C21 -> 5000000 | E21: =Indata!C21 -> 500
B22: Summa investering | C22: =SUM(C17:C21) -> 15000 | D22: =Indata!R31 -> 200000000
B24: Projektbeskrivning
B25: [Fyll i en kort beskrivning av projektet — bakgrund, vision, kvalitetsambition, tidplan.]
B29: VISUALISERING
B30: [Projektunik bild] | G30: [Karta över fastigheten]
B39: MARKNADSSITUATION
B40: Marknadsvärde, senaste värdering | C40: Fyll i | G40: Värderingsdatum | H40: Fyll i
B42: Byggrätter | C42: Före projekt | D42: Efter projekt
B43: Utnyttjade byggrätter | C43: Fyll i | D43: Fyll i
B44: Outnyttjade byggrätter | C44: Fyll i | D44: Fyll i
B46: KALKYLANTAGANDEN
B47: Kalkylperiod | C47: =Indata!C16 -> 20 | G47: Avskrivningstid | H47: =Indata!C19 -> 33
B48: Direktavkastningskrav, marknad | C48: =Indata!$D$81 -> 0.05 | G48: Kalkylränta driftnetto | H48: =Indata!C7 -> 0.04
B49: Kalkylränta restvärde | C49: =Indata!C9 -> 0.07 | G49: Inflation | H49: =Indata!C8 -> 0.02
B52: HYRESANTAGANDEN
B53: Bindande kravhyra | C53: =Resultat!D14 -> 11631222 | G53: Per kvm/år | H53: =Resultat!D16 -> 2326.2443
B54: Hyresspann lägsta (−) | C54: =Resultat!C14 -> 10726244 | G54: Lägsta per kvm | H54: =Resultat!C16 -> 2145.2489
B55: Hyresspann högsta (+) | C55: =Resultat!E14 -> 12536199 | G55: Högsta per kvm | H55: =Resultat!E16 -> 2507.2398
B56: Långsiktig vakansrisk | C56: =Indata!C11 -> 0 | G56: Drift & underhåll | H56: =Indata!C41 -> 0
B58: FINANSIERINGSANTAGANDEN
B59: Långsiktig räntenivå | C59: =Indata!C62 -> 0.04 | G59: Belåningsgrad | H59: =Indata!C64 -> 0.37
...

Sheet Indata
B1: LEJONFASTIGHETER · INDATA
A2: 'Försättsblad'!A1 | B2: Indata
A3: 'Översikt'!A1 | B3: Investeringsförutsättningar och parametrar
B4: 1. MARKNADS- OCH FASTIGHETSFÖRUTSÄTTNINGAR
A5: 'Kassaflöde'!A1 | B5: Kalkylstart (år) | C5: 2026 | D5: år | E5: Första året i kassaflödet
A6: 'Finansiering'!A1 | B6: Direktavkastning marknad | C6: 0.05 | D6: % | E6: Avkastningskrav, från senaste värdering
A7: 'Resultat'!A1 | B7: Kalkylränta driftnetto | C7: 0.04 | D7: % | E7: Företagets diskonteringsränta (NPV-kravet)
A8: 'Grafer'!A1 | B8: Inflation | C8: 0.02 | D8: % | E8: Årlig KPI-uppräkning
A9: 'Lönsamhetskontroll'!A1 | B9: Kalkylränta restvärde | C9: =C6+C8 -> 0.07 | D9: % | E9: Auto = direktavkastning + inflation
A10: 'Beräkningslogik'!A1 | B10: Bolagsskatt | C10: 0.206 | D10: % | E10: För IRR-beräkning
A11: 'Dokumentation'!A1 | B11: Långsiktig vakansnivå | C11: 0 | D11: % | E11: Default efter avtalsslut
B12: Momsregistreringsgrad före | C12: 1 | D12: %
B13: Momsregistreringsgrad efter | C13: 1 | D13: %
A15: INVESTERING | B15: 2. INVESTERING OCH AVSKRIVNING
B16: Kalkylperiod | C16: 20 | D16: år | E16: Standard 20
B17: Byggnadsvärde (avskrivningsbas) | C17: 200000000 | D17: kr | E17: Investering exkl. mark (påverkar avskrivning och IRR)
B18: Avskrivningstakt | C18: 0.03 | D18: % | E18: 3% = 33 års livslängd
B19: Avskrivningstid | C19: =ROUND(1/C18,0) -> 33 | D19: år | E19: Auto
B20: Fastighetsarea (mark) | C20: 10000 | D20: kvm | E20: Total markarea
B21: Markvärde | C21: 500 | D21: kr/kvm | E21: För minsta markvärde
B22: Minsta markvärde (totalt) | C22: =C20*C21 -> 5000000 | D22: kr | E22: Auto
B23: HYRESLÄGE | C23: Beräkna | E23: Beräkna = mallen räknar kravhyran. Ange = manuell (ej aktiv än)
A24: HYRESOBJEKT | B24: 3. HYRESOBJEKT (upp till 5)
B25: Objektnamn | C25: Typ | D25: Bef area | E25: Nyb area | F25: Total | G25: (ej använd) | H25: Index | I25: (ej använd) | J25: Andel | K25: Avtalsstart | L25: Avtalsslut | M25: Hyra efter avtal | N25: Vakans% | O25: Prod start | P25: Prod slut | Q25: Budget kr/kvm | R25: Investering
B26: Skola | C26: Nyb | D26: 0 | E26: 5000 | F26: =D26+E26 -> 5000 | G26: 0 | H26: 0.7 | I26: 0 | J26: =IFERROR(R26/$R$31,0) -> 1 | K26: 2026 | L26: 2045 | N26: 0 | O26: 2025 | P26: 2026 | Q26: 40000 | R26: =IFERROR(Q26*F26,0) -> 200000000
F27: =D27+E27 -> 0 | G27: 0 | I27: 0 | J27: =IFERROR(R27/$R$31,0) -> 0 | R27: =IFERROR(Q27*F27,0) -> 0
F28: =D28+E28 -> 0 | G28: 0 | I28: 0 | J28: =IFERROR(R28/$R$31,0) -> 0 | R28: =IFERROR(Q28*F28,0) -> 0
F29: =D29+E29 -> 0 | G29: 0 | I29: 0 | J29: =IFERROR(R29/$R$31,0) -> 0 | R29: =IFERROR(Q29*F29,0) -> 0
F30: =D30+E30 -> 0 | G30: 0 | I30: 0 | J30: =IFERROR(R30/$R$31,0) -> 0 | R30: =IFERROR(Q30*F30,0) -> 0
B31: Summa | D31: =SUM(D26:D30) -> 0 | E31: =SUM(E26:E30) -> 5000 | F31: =SUM(F26:F30) -> 5000 | R31: =SUM(R26:R30) -> 200000000
B32: ⓘ "Hyra efter avtal" (M) används endast efter avtalsslut. Lämna tomt för monopolmodell (samma kr/m² fortsätter). Fyll i för korta avtal. Se Dokumentation sektion 13.
A34: DRIFT & UH | B34: 4. DRIFT OCH UNDERHÅLL (kr/kvm/år)
B35: Kostnadspost | C35: Befintligt | D35: Nybyggnad | E35: DoU-höjning från år 11 | F35: Ytterligare höjning från år 16
B36: Fastighetsskötsel | C36: 0 | D36: 50 | E36: 0 | F36: 0
B37: Reparationer | C37: 0 | D37: 30 | E37: 0 | F37: 0
B38: Planerat underhåll | C38: 0 | D38: 40 | E38: 0 | F38: 0
B39: Media | C39: 0 | D39: 150 | E39: 0 | F39: 0
B40: Övriga förvaltningskostnader | C40: 0 | D40: 130 | E40: 0 | F40: 0
B41: Summa drift | C41: =SUM(C36:C40) -> 0 | D41: =SUM(D36:D40) -> 400
A43: RE-INVEST. | B43: 5. RE-INVESTERING / HYRESATT UH
...

Sheet Kassaflöde
B1: LEJONFASTIGHETER · KASSAFLÖDE
A2: 'Försättsblad'!A1 | B2: Kassaflöde
A3: 'Översikt'!A1 | B3: Driftnettoprojektion över kalkylperioden | D3: =Indata!$C$5+0 -> 2026 | E3: =Indata!$C$5+1 -> 2027 | F3: =Indata!$C$5+2 -> 2028 | G3: =Indata!$C$5+3 -> 2029 | H3: =Indata!$C$5+4 -> 2030 | I3: =Indata!$C$5+5 -> 2031 | J3: =Indata!$C$5+6 -> 2032 | K3: =Indata!$C$5+7 -> 2033 | L3: =Indata!$C$5+8 -> 2034 | M3: =Indata!$C$5+9 -> 2035 | N3: =Indata!$C$5+10 -> 2036 | O3: =Indata!$C$5+11 -> 2037 | P3: =Indata!$C$5+12 -> 2038 | Q3: =Indata!$C$5+13 -> 2039 | R3: =Indata!$C$5+14 -> 2040 | S3: =Indata!$C$5+15 -> 2041 | T3: =Indata!$C$5+16 -> 2042 | U3: =Indata!$C$5+17 -> 2043 | V3: =Indata!$C$5+18 -> 2044 | W3: =Indata!$C$5+19 -> 2045 | X3: =Indata!$C$5+20 -> 2046 | Y3: =Indata!$C$5+21 -> 2047 | Z3: =Indata!$C$5+22 -> 2048 | AA3: =Indata!$C$5+23 -> 2049 | AB3: =Indata!$C$5+24 -> 2050
A4: 'Indata'!A1 | B4: År i kalkyl | D4: 1 | E4: 2 | F4: 3 | G4: 4 | H4: 5 | I4: 6 | J4: 7 | K4: 8 | L4: 9 | M4: 10 | N4: 11 | O4: 12 | P4: 13 | Q4: 14 | R4: 15 | S4: 16 | T4: 17 | U4: 18 | V4: 19 | W4: 20 | X4: 21 | Y4: 22 | Z4: 23 | AA4: 24 | AB4: 25
B5: Inom kalkylperiod | D5: =IF(D4<=Indata!$C$16,1,0) -> 1 | E5: =IF(E4<=Indata!$C$16,1,0) -> 1 | F5: =IF(F4<=Indata!$C$16,1,0) -> 1 | G5: =IF(G4<=Indata!$C$16,1,0) -> 1 | H5: =IF(H4<=Indata!$C$16,1,0) -> 1 | I5: =IF(I4<=Indata!$C$16,1,0) -> 1 | J5: =IF(J4<=Indata!$C$16,1,0) -> 1 | K5: =IF(K4<=Indata!$C$16,1,0) -> 1 | ... AB5: =IF(AB4<=Indata!$C$16,1,0) -> 0
A6: 'Finansiering'!A1 | B6: Area Nyb (aktiv) | D6: =SUMIFS(Indata!$E$26:$E$30,Indata!$C$26:$C$30,"Nyb",Indata!$P$26:$P$30,"<="&D3)+SUMIFS(Indata!$E$26:$E$30,Indata!$C$26:$C$30,"Omb",Indata!$P$26:$P$30,"<="&D3)+SUMIFS(Indata!$E$26:$E$30,Indata!$C$26:$C$30,"Ins",Indata!$P$26:$P$30,"<="&D3) -> 5000 | E6: =SUMIFS(Indata!$E$26:$E$30,Indata!$C$26:$C$30,"Nyb",Indata!$P$26:$P$30,"<="&E3)+SUMIFS(Indata!$E$26:$E$30,Indata!$C$26:$C$30,"Omb",Indata!$P$26:$P$30,"<="&E3)+SUMIFS(Indata!$E$26:$E$30,Indata!$C$26:$C$30,"Ins",Indata!$P$26:$P$30,"<="&E3) -> 5000 | F6: =SUMIFS(Indata!$E$26:$E$30,Indata!$C$26:$C$30,"Nyb",Indata!$P$26:$P$30,"<="&F3)+SUMIFS(Indata!$E$26:$E$30,Indata!$C$26:$C$30,"Omb",Indata!$P$26:$P$30,"<="&F3)+SUMIFS(Indata!$E$26:$E$30,Indata!$C$26:$C$30,"Ins",Indata!$P$26:$P$30,"<="&F3) -> 5000 | G6: =SUMIFS(Indata!$E$26:$E$30,Indata!$C$26:$C$30,"Nyb",Indata!$P$26:$P$30,"<="&G3)+SUMIFS(Indata!$E$26:$E$30,Indata!$C$26:$C$30,"Omb",Indata!$P$26:$P$30,"<="&G3)+SUMIFS(Indata!$E$26:$E$30,Indata!$C$26:$C$30,"Ins",Indata!$P$26:$P$30,"<="&G3) -> 5000 | H6: =SUMIFS(Indata!$E$26:$E$30,Indata!$C$26:$C$30,"Nyb",Indata!$P$26:$P$30,"<="&H3)+SUMIFS(Indata!$E$26:$E$30,Indata!$C$26:$C$30,"Omb",Indata!$P$26:$P$30,"<="&H3)+SUMIFS(Indata!$E$26:$E$30,Indata!$C$26:$C$30,"Ins",Indata!$P$26:$P$30,"<="&H3) -> 5000 | I6: =SUMIFS(Indata!$E$26:$E$30,Indata!$C$26:$C$30,"Nyb",Indata!$P$26:$P$30,"<="&I3)+SUMIFS(Indata!$E$26:$E$30,Indata!$C$26:$C$30,"Omb",Indata!$P$26:$P$30,"<="&I3)+SUMIFS(Indata!$E$26:$E$30,Indata!$C$26:$C$30,"Ins",Indata!$P$26:$P$30,"<="&I3) -> 5000 | J6: =SUMIFS(Indata!$E$26:$E$30,Indata!$C$26:$C$30,"Nyb",Indata!$P$26:$P$30,"<="&J3)+SUMIFS(Indata!$E$26:$E$30,Indata!$C$26:$C$30,"Omb",Indata!$P$26:$P$30,"<="&J3)+SUMIFS(Indata!$E$26:$E$30,Indata!$C$26:$C$30,"Ins",Indata!$P$26:$P$30,"<="&J3) -> 5000 | K6: =SUMIFS(Indata!$E$26:$E$30,Indata!$C$26:$C$30,"Nyb",Indata!$P$26:$P$30,"<="&K3)+SUMIFS(Indata!$E$26:$E$30,Indata!$C$26:$C$30,"Omb",Indata!$P$26:$P$30,"<="&K3)+SUMIFS(Indata!$E$26:$E$30,Indata!$C$26:$C$30,"Ins",Indata!$P$26:$P$30,"<="&K3) -> 5000 | ... AB6: =SUMIFS(Indata!$E$26:$E$30,Indata!$C$26:$C$30,"Nyb",Indata!$P$26:$P$30,"<="&AB3)+SUMIFS(Indata!$E$26:$E$30,Indata!$C$26:$C$30,"Omb",Indata!$P$26:$P$30,"<="&AB3)+SUMIFS(Indata!$E$26:$E$30,Indata!$C$26:$C$30,"Ins",Indata!$P$26:$P$30,"<="&AB3) -> 5000
A7: 'Resultat'!A1 | B7: Area Bef (aktiv) | D7: =SUMIFS(Indata!$D$26:$D$30,Indata!$C$26:$C$30,"Bef",Indata!$P$26:$P$30,"<="&D3)+SUMIFS(Indata!$D$26:$D$30,Indata!$C$26:$C$30,"Omb",Indata!$P$26:$P$30,"<="&D3)+SUMIFS(Indata!$D$26:$D$30,Indata!$C$26:$C$30,"Nyb",Indata!$P$26:$P$30,"<="&D3)+SUMIFS(Indata!$D$26:$D$30,Indata!$C$26:$C$30,"Ins",Indata!$P$26:$P$30,"<="&D3) -> 0 | E7: =SUMIFS(Indata!$D$26:$D$30,Indata!$C$26:$C$30,"Bef",Indata!$P$26:$P$30,"<="&E3)+SUMIFS(Indata!$D$26:$D$30,Indata!$C$26:$C$30,"Omb",Indata!$P$26:$P$30,"<="&E3)+SUMIFS(Indata!$D$26:$D$30,Indata!$C$26:$C$30,"Nyb",Indata!$P$26:$P$30,"<="&E3)+SUMIFS(Indata!$D$26:$D$30,Indata!$C$26:$C$30,"Ins",Indata!$P$26:$P$30,"<="&E3) -> 0 | F7: =SUMIFS(Indata!$D$26:$D$30,Indata!$C$26:$C$30,"Bef",Indata!$P$26:$P$30,"<="&F3)+SUMIFS(Indata!$D$26:$D$30,Indata!$C$26:$C$30,"Omb",Indata!$P$26:$P$30,"<="&F3)+SUMIFS(Indata!$D$26:$D$30,Indata!$C$26:$C$30,"Nyb",Indata!$P$26:$P$30,"<="&F3)+SUMIFS(Indata!$D$26:$D$30,Indata!$C$26:$C$30,"Ins",Indata!$P$26:$P$30,"<="&F3) -> 0 | G7: =SUMIFS(Indata!$D$26:$D$30,Indata!$C$26:$C$30,"Bef",Indata!$P$26:$P$30,"<="&G3)+SUMIFS(Indata!$D$26:$D$30,Indata!$C$26:$C$30,"Omb",Indata!$P$26:$P$30,"<="&G3)+SUMIFS(Indata!$D$26:$D$30,Indata!$C$26:$C$30,"Nyb",Indata!$P$26:$P$30,"<="&G3)+SUMIFS(Indata!$D$26:$D$30,Indata!$C$26:$C$30,"Ins",Indata!$P$26:$P$30,"<="&G3) -> 0 | H7: =SUMIFS(Indata!$D$26:$D$30,Indata!$C$26:$C$30,"Bef",Indata!$P$26:$P$30,"<="&H3)+SUMIFS(Indata!$D$26:$D$30,Indata!$C$26:$C$30,"Omb",Indata!$P$26:$P$30,"<="&H3)+SUMIFS(Indata!$D$26:$D$30,Indata!$C$26:$C$30,"Nyb",Indata!$P$26:$P$30,"<="&H3)+SUMIFS(Indata!$D$26:$D$30,Indata!$C$26:$C$30,"Ins",Indata!$P$26:$P$30,"<="&H3) -> 0 | I7: =SUMIFS(Indata!$D$26:$D$30,Indata!$C$26:$C$30,"Bef",Indata!$P$26:$P$30,"<="&I3)+SUMIFS(Indata!$D$26:$D$30,Indata!$C$26:$C$30,"Omb",Indata!$P$26:$P$30,"<="&I3)+SUMIFS(Indata!$D$26:$D$30,Indata!$C$26:$C$30,"Nyb",Indata!$P$26:$P$30,"<="&I3)+SUMIFS(Indata!$D$26:$D$30,Indata!$C$26:$C$30,"Ins",Indata!$P$26:$P$30,"<="&I3) -> 0 | J7: =SUMIFS(Indata!$D$26:$D$30,Indata!$C$26:$C$30,"Bef",Indata!$P$26:$P$30,"<="&J3)+SUMIFS(Indata!$D$26:$D$30,Indata!$C$26:$C$30,"Omb",Indata!$P$26:$P$30,"<="&J3)+SUMIFS(Indata!$D$26:$D$30,Indata!$C$26:$C$30,"Nyb",Indata!$P$26:$P$30,"<="&J3)+SUMIFS(Indata!$D$26:$D$30,Indata!$C$26:$C$30,"Ins",Indata!$P$26:$P$30,"<="&J3) -> 0 | K7: =SUMIFS(Indata!$D$26:$D$30,Indata!$C$26:$C$30,"Bef",Indata!$P$26:$P$30,"<="&K3)+SUMIFS(Indata!$D$26:$D$30,Indata!$C$26:$C$30,"Omb",Indata!$P$26:$P$30,"<="&K3)+SUMIFS(Indata!$D$26:$D$30,Indata!$C$26:$C$30,"Nyb",Indata!$P$26:$P$30,"<="&K3)+SUMIFS(Indata!$D$26:$D$30,Indata!$C$26:$C$30,"Ins",Indata!$P$26:$P$30,"<="&K3) -> 0 | ... AB7: =SUMIFS(Indata!$D$26:$D$30,Indata!$C$26:$C$30,"Bef",Indata!$P$26:$P$30,"<="&AB3)+SUMIFS(Indata!$D$26:$D$30,Indata!$C$26:$C$30,"Omb",Indata!$P$26:$P$30,"<="&AB3)+SUMIFS(Indata!$D$26:$D$30,Indata!$C$26:$C$30,"Nyb",Indata!$P$26:$P$30,"<="&AB3)+SUMIFS(Indata!$D$26:$D$30,Indata!$C$26:$C$30,"Ins",Indata!$P$26:$P$30,"<="&AB3) -> 0
A8: 'Grafer'!A1 | B8: Total area | D8: =D6+D7 -> 5000 | E8: =E6+E7 -> 5000 | F8: =F6+F7 -> 5000 | G8: =G6+G7 -> 5000 | H8: =H6+H7 -> 5000 | I8: =I6+I7 -> 5000 | J8: =J6+J7 -> 5000 | K8: =K6+K7 -> 5000 | ... AB8: =AB6+AB7 -> 5000
A9: 'Lönsamhetskontroll'!A1
A10: 'Beräkningslogik'!A1 | B10: DRIFTNETTO-PROJEKTION vid bindande kravhyra
A11: 'Dokumentation'!A1 | B11: Projektets driftnetto år för år vid den hyra mallen räknat fram. Detta är kassaflödet före finansiering — för bokföringsmässig vy med ränta och avskrivning, se Finansiering-fliken.
B13: Bindande kravhyra (kr/år) | C13: =Resultat!D14 -> 11631222
B14: Bindande krav | C14: =Resultat!D15 -> NPV
B16: Bruttohyra | D16: =Beräkningslogik!D66+($C$13/1000000)*(Beräkningslogik!D129-Beräkningslogik!D66) -> 11631222 | E16: =Beräkningslogik!E66+($C$13/1000000)*(Beräkningslogik!E129-Beräkningslogik!E66) -> 11794059 | F16: =Beräkningslogik!F66+($C$13/1000000)*(Beräkningslogik!F129-Beräkningslogik!F66) -> 11959176 | G16: =Beräkningslogik!G66+($C$13/1000000)*(Beräkningslogik!G129-Beräkningslogik!G66) -> 12126604 | H16: =Beräkningslogik!H66+($C$13/1000000)*(Beräkningslogik!H129-Beräkningslogik!H66) -> 12296377 | I16: =Beräkningslogik!I66+($C$13/1000000)*(Beräkningslogik!I129-Beräkningslogik!I66) -> 12468526 | J16: =Beräkningslogik!J66+($C$13/1000000)*(Beräkningslogik!J129-Beräkningslogik!J66) -> 12643085 | K16: =Beräkningslogik!K66+($C$13/1000000)*(Beräkningslogik!K129-Beräkningslogik!K66) -> 12820088 | ... AB16: =Beräkningslogik!AB66+($C$13/1000000)*(Beräkningslogik!AB129-Beräkningslogik!AB66) -> 16238139
B17: Vakans | D17: =Beräkningslogik!D67+($C$13/1000000)*(Beräkningslogik!D130-Beräkningslogik!D67) -> 0 | E17: =Beräkningslogik!E67+($C$13/1000000)*(Beräkningslogik!E130-Beräkningslogik!E67) -> 0 | F17: =Beräkningslogik!F67+($C$13/1000000)*(Beräkningslogik!F130-Beräkningslogik!F67) -> 0 | G17: =Beräkningslogik!G67+($C$13/1000000)*(Beräkningslogik!G130-Beräkningslogik!G67) -> 0 | H17: =Beräkningslogik!H67+($C$13/1000000)*(Beräkningslogik!H130-Beräkningslogik!H67) -> 0 | I17: =Beräkningslogik!I67+($C$13/1000000)*(Beräkningslogik!I130-Beräkningslogik!I67) -> 0 | J17: =Beräkningslogik!J67+($C$13/1000000)*(Beräkningslogik!J130-Beräkningslogik!J67) -> 0 | K17: =Beräkningslogik!K67+($C$13/1000000)*(Beräkningslogik!K130-Beräkningslogik!K67) -> 0 | ... AB17: =Beräkningslogik!AB67+($C$13/1000000)*(Beräkningslogik!AB130-Beräkningslogik!AB67) -> 0
B18: Nettohyra | D18: =Beräkningslogik!D68+($C$13/1000000)*(Beräkningslogik!D131-Beräkningslogik!D68) -> 11631222 | E18: =Beräkningslogik!E68+($C$13/1000000)*(Beräkningslogik!E131-Beräkningslogik!E68) -> 11794059 | F18: =Beräkningslogik!F68+($C$13/1000000)*(Beräkningslogik!F131-Beräkningslogik!F68) -> 11959176 | G18: =Beräkningslogik!G68+($C$13/1000000)*(Beräkningslogik!G131-Beräkningslogik!G68) -> 12126604 | H18: =Beräkningslogik!H68+($C$13/1000000)*(Beräkningslogik!H131-Beräkningslogik!H68) -> 12296377 | I18: =Beräkningslogik!I68+($C$13/1000000)*(Beräkningslogik!I131-Beräkningslogik!I68) -> 12468526 | J18: =Beräkningslogik!J68+($C$13/1000000)*(Beräkningslogik!J131-Beräkningslogik!J68) -> 12643085 | K18: =Beräkningslogik!K68+($C$13/1000000)*(Beräkningslogik!K131-Beräkningslogik!K68) -> 12820088 | ... AB18: =Beräkningslogik!AB68+($C$13/1000000)*(Beräkningslogik!AB131-Beräkningslogik!AB68) -> 16238139
B19: Drift och underhåll | D19: =Beräkningslogik!D77 -> -2000000 | E19: =Beräkningslogik!E77 -> -2040000 | F19: =Beräkningslogik!F77 -> -2080800 | G19: =Beräkningslogik!G77 -> -2122416 | H19: =Beräkningslogik!H77 -> -2164864.3 | I19: =Beräkningslogik!I77 -> -2208161.6 | J19: =Beräkningslogik!J77 -> -2252324.8 | K19: =Beräkningslogik!K77 -> -2297371.3 | ... AB19: =Beräkningslogik!AB77 -> -3216874.5
B20: Fastighetsskatt | D20: =Beräkningslogik!D79 -> 0 | E20: =Beräkningslogik!E79 -> 0 | F20: =Beräkningslogik!F79 -> 0 | G20: =Beräkningslogik!G79 -> 0 | H20: =Beräkningslogik!H79 -> 0 | I20: =Beräkningslogik!I79 -> 0 | J20: =Beräkningslogik!J79 -> 0 | K20: =Beräkningslogik!K79 -> 0 | ... AB20: =Beräkningslogik!AB79 -> 0
B21: Tomträttsavgäld | D21: =Beräkningslogik!D80 -> 0 | E21: =Beräkningslogik!E80 -> 0 | F21: =Beräkningslogik!F80 -> 0 | G21: =Beräkningslogik!G80 -> 0 | H21: =Beräkningslogik!H80 -> 0 | I21: =Beräkningslogik!I80 -> 0 | J21: =Beräkningslogik!J80 -> 0 | K21: =Beräkningslogik!K80 -> 0 | ... AB21: =Beräkningslogik!AB80 -> 0
B22: Central administration | D22: =Beräkningslogik!D83 -> -400000 | E22: =Beräkningslogik!E83 -> -408000 | F22: =Beräkningslogik!F83 -> -416160 | G22: =Beräkningslogik!G83 -> -424483.2 | H22: =Beräkningslogik!H83 -> -432972.86 | I22: =Beräkningslogik!I83 -> -441632.32 | J22: =Beräkningslogik!J83 -> -450464.97 | K22: =Beräkningslogik!K83 -> -459474.27 | ... AB22: =Beräkningslogik!AB83 -> -643374.9
B23: DRIFTNETTO | D23: =Beräkningslogik!D82+($C$13/1000000)*(Beräkningslogik!D132-Beräkningslogik!D82) -> 9231221.7 | E23: =Beräkningslogik!E82+($C$13/1000000)*(Beräkningslogik!E132-Beräkningslogik!E82) -> 9346058.8 | F23: =Beräkningslogik!F82+($C$13/1000000)*(Beräkningslogik!F132-Beräkningslogik!F82) -> 9462215.6 | G23: =Beräkningslogik!G82+($C$13/1000000)*(Beräkningslogik!G132-Beräkningslogik!G82) -> 9579704.9 | H23: =Beräkningslogik!H82+($C$13/1000000)*(Beräkningslogik!H132-Beräkningslogik!H82) -> 9698539.4 | I23: =Beräkningslogik!I82+($C$13/1000000)*(Beräkningslogik!I132-Beräkningslogik!I82) -> 9818731.9 | J23: =Beräkningslogik!J82+($C$13/1000000)*(Beräkningslogik!J132-Beräkningslogik!J82) -> 9940295.4 | K23: =Beräkningslogik!K82+($C$13/1000000)*(Beräkningslogik!K132-Beräkningslogik!K82) -> 10063243 | ... AB23: =Beräkningslogik!AB82+($C$13/1000000)*(Beräkningslogik!AB132-Beräkningslogik!AB82) -> 12377890
B26: INFASNING — hyresintäkt under uppstart
B27: Vid mål-utfall och bindande kravhyra. Visar etappvis tillträde under uppstartsår.
B29: Objekt | D29: =Indata!$C$5+0 -> 2026 | E29: =Indata!$C$5+1 -> 2027 | F29: =Indata!$C$5+2 -> 2028 | G29: =Indata!$C$5+3 -> 2029 | H29: =Indata!$C$5+4 -> 2030 | I29: =Indata!$C$5+5 -> 2031 | J29: =Indata!$C$5+6 -> 2032 | K29: =Indata!$C$5+7 -> 2033 | L29: =Indata!$C$5+8 -> 2034 | M29: =Indata!$C$5+9 -> 2035
B30: =IF(Indata!B26="","",Indata!B26) -> Skola | D30: =IF(OR(Indata!$K$26="",D$29<Indata!$K$26),0,(Indata!$R$26/Indata!$R$31)*D$16) -> 11631222 | E30: =IF(OR(Indata!$K$26="",E$29<Indata!$K$26),0,(Indata!$R$26/Indata!$R$31)*E$16) -> 11794059 | F30: =IF(OR(Indata!$K$26="",F$29<Indata!$K$26),0,(Indata!$R$26/Indata!$R$31)*F$16) -> 11959176 | G30: =IF(OR(Indata!$K$26="",G$29<Indata!$K$26),0,(Indata!$R$26/Indata!$R$31)*G$16) -> 12126604 | H30: =IF(OR(Indata!$K$26="",H$29<Indata!$K$26),0,(Indata!$R$26/Indata!$R$31)*H$16) -> 12296377 | I30: =IF(OR(Indata!$K$26="",I$29<Indata!$K$26),0,(Indata!$R$26/Indata!$R$31)*I$16) -> 12468526 | J30: =IF(OR(Indata!$K$26="",J$29<Indata!$K$26),0,(Indata!$R$26/Indata!$R$31)*J$16) -> 12643085 | K30: =IF(OR(Indata!$K$26="",K$29<Indata!$K$26),0,(Indata!$R$26/Indata!$R$31)*K$16) -> 12820088 | ... AB30: =IF(OR(Indata!$K$26="",AB$29<Indata!$K$26),0,(Indata!$R$26/Indata!$R$31)*AB$16) -> 0
B31: =IF(Indata!B27="","",Indata!B27) | D31: =IF(OR(Indata!$K$27="",D$29<Indata!$K$27),0,(Indata!$R$27/Indata!$R$31)*D$16) -> 0 | E31: =IF(OR(Indata!$K$27="",E$29<Indata!$K$27),0,(Indata!$R$27/Indata!$R$31)*E$16) -> 0 | F31: =IF(OR(Indata!$K$27="",F$29<Indata!$K$27),0,(Indata!$R$27/Indata!$R$31)*F$16) -> 0 | G31: =IF(OR(Indata!$K$27="",G$29<Indata!$K$27),0,(Indata!$R$27/Indata!$R$31)*G$16) -> 0 | H31: =IF(OR(Indata!$K$27="",H$29<Indata!$K$27),0,(Indata!$R$27/Indata!$R$31)*H$16) -> 0 | I31: =IF(OR(Indata!$K$27="",I$29<Indata!$K$27),0,(Indata!$R$27/Indata!$R$31)*I$16) -> 0 | J31: =IF(OR(Indata!$K$27="",J$29<Indata!$K$27),0,(Indata!$R$27/Indata!$R$31)*J$16) -> 0 | K31: =IF(OR(Indata!$K$27="",K$29<Indata!$K$27),0,(Indata!$R$27/Indata!$R$31)*K$16) -> 0 | ... AB31: =IF(OR(Indata!$K$27="",AB$29<Indata!$K$27),0,(Indata!$R$27/Indata!$R$31)*AB$16) -> 0
B32: =IF(Indata!B28="","",Indata!B28) | D32: =IF(OR(Indata!$K$28="",D$29<Indata!$K$28),0,(Indata!$R$28/Indata!$R$31)*D$16) -> 0 | E32: =IF(OR(Indata!$K$28="",E$29<Indata!$K$28),0,(Indata!$R$28/Indata!$R$31)*E$16) -> 0 | F32: =IF(OR(Indata!$K$28="",F$29<Indata!$K$28),0,(Indata!$R$28/Indata!$R$31)*F$16) -> 0 | G32: =IF(OR(Indata!$K$28="",G$29<Indata!$K$28),0,(Indata!$R$28/Indata!$R$31)*G$16) -> 0 | H32: =IF(OR(Indata!$K$28="",H$29<Indata!$K$28),0,(Indata!$R$28/Indata!$R$31)*H$16) -> 0 | I32: =IF(OR(Indata!$K$28="",I$29<Indata!$K$28),0,(Indata!$R$28/Indata!$R$31)*I$16) -> 0 | J32: =IF(OR(Indata!$K$28="",J$29<Indata!$K$28),0,(Indata!$R$28/Indata!$R$31)*J$16) -> 0 | K32: =IF(OR(Indata!$K$28="",K$29<Indata!$K$28),0,(Indata!$R$28/Indata!$R$31)*K$16) -> 0 | ... AB32: =IF(OR(Indata!$K$28="",AB$29<Indata!$K$28),0,(Indata!$R$28/Indata!$R$31)*AB$16) -> 0
B33: =IF(Indata!B29="","",Indata!B29) | D33: =IF(OR(Indata!$K$29="",D$29<Indata!$K$29),0,(Indata!$R$29/Indata!$R$31)*D$16) -> 0 | E33: =IF(OR(Indata!$K$29="",E$29<Indata!$K$29),0,(Indata!$R$29/Indata!$R$31)*E$16) -> 0 | F33: =IF(OR(Indata!$K$29="",F$29<Indata!$K$29),0,(Indata!$R$29/Indata!$R$31)*F$16) -> 0 | G33: =IF(OR(Indata!$K$29="",G$29<Indata!$K$29),0,(Indata!$R$29/Indata!$R$31)*G$16) -> 0 | H33: =IF(OR(Indata!$K$29="",H$29<Indata!$K$29),0,(Indata!$R$29/Indata!$R$31)*H$16) -> 0 | I33: =IF(OR(Indata!$K$29="",I$29<Indata!$K$29),0,(Indata!$R$29/Indata!$R$31)*I$16) -> 0 | J33: =IF(OR(Indata!$K$29="",J$29<Indata!$K$29),0,(Indata!$R$29/Indata!$R$31)*J$16) -> 0 | K33: =IF(OR(Indata!$K$29="",K$29<Indata!$K$29),0,(Indata!$R$29/Indata!$R$31)*K$16) -> 0 | ... AB33: =IF(OR(Indata!$K$29="",AB$29<Indata!$K$29),0,(Indata!$R$29/Indata!$R$31)*AB$16) -> 0
B34: =IF(Indata!B30="","",Indata!B30) | D34: =IF(OR(Indata!$K$30="",D$29<Indata!$K$30),0,(Indata!$R$30/Indata!$R$31)*D$16) -> 0 | E34: =IF(OR(Indata!$K$30="",E$29<Indata!$K$30),0,(Indata!$R$30/Indata!$R$31)*E$16) -> 0 | F34: =IF(OR(Indata!$K$30="",F$29<Indata!$K$30),0,(Indata!$R$30/Indata!$R$31)*F$16) -> 0 | G34: =IF(OR(Indata!$K$30="",G$29<Indata!$K$30),0,(Indata!$R$30/Indata!$R$31)*G$16) -> 0 | H34: =IF(OR(Indata!$K$30="",H$29<Indata!$K$30),0,(Indata!$R$30/Indata!$R$31)*H$16) -> 0 | I34: =IF(OR(Indata!$K$30="",I$29<Indata!$K$30),0,(Indata!$R$30/Indata!$R$31)*I$16) -> 0 | J34: =IF(OR(Indata!$K$30="",J$29<Indata!$K$30),0,(Indata!$R$30/Indata!$R$31)*J$16) -> 0 | K34: =IF(OR(Indata!$K$30="",K$29<Indata!$K$30),0,(Indata!$R$30/Indata!$R$31)*K$16) -> 0 | ... AB34: =IF(OR(Indata!$K$30="",AB$29<Indata!$K$30),0,(Indata!$R$30/Indata!$R$31)*AB$16) -> 0
B35: Summa | D35: =SUM(D30:D34) -> 11631222 | E35: =SUM(E30:E34) -> 11794059 | F35: =SUM(F30:F34) -> 11959176 | G35: =SUM(G30:G34) -> 12126604 | H35: =SUM(H30:H34) -> 12296377 | I35: =SUM(I30:I34) -> 12468526 | J35: =SUM(J30:J34) -> 12643085 | K35: =SUM(K30:K34) -> 12820088 | ... M35: =SUM(M30:M34) -> 13181564
B36: Andel av fullt flöde | D36: =IFERROR(D35/D16,0) -> 1 | E36: =IFERROR(E35/E16,0) -> 1 | F36: =IFERROR(F35/F16,0) -> 1 | G36: =IFERROR(G35/G16,0) -> 1 | H36: =IFERROR(H35/H16,0) -> 1 | I36: =IFERROR(I35/I16,0) -> 1 | J36: =IFERROR(J35/J16,0) -> 1 | K36: =IFERROR(K35/K16,0) -> 1 | ... AB36: =IFERROR(AB35/AB16,0) -> 0

Sheet Finansiering
B1: LEJONFASTIGHETER · FINANSIERING
A2: 'Försättsblad'!A1 | B2: Finansiering
A3: 'Översikt'!A1 | B3: Lån, ränta, amortering och avskrivning | D3: =Indata!$C$5+0 -> 2026 | E3: =Indata!$C$5+1 -> 2027 | F3: =Indata!$C$5+2 -> 2028 | G3: =Indata!$C$5+3 -> 2029 | H3: =Indata!$C$5+4 -> 2030 | I3: =Indata!$C$5+5 -> 2031 | J3: =Indata!$C$5+6 -> 2032 | K3: =Indata!$C$5+7 -> 2033 | L3: =Indata!$C$5+8 -> 2034 | M3: =Indata!$C$5+9 -> 2035 | N3: =Indata!$C$5+10 -> 2036 | O3: =Indata!$C$5+11 -> 2037 | P3: =Indata!$C$5+12 -> 2038 | Q3: =Indata!$C$5+13 -> 2039 | R3: =Indata!$C$5+14 -> 2040 | S3: =Indata!$C$5+15 -> 2041 | T3: =Indata!$C$5+16 -> 2042 | U3: =Indata!$C$5+17 -> 2043 | V3: =Indata!$C$5+18 -> 2044 | W3: =Indata!$C$5+19 -> 2045 | X3: =Indata!$C$5+20 -> 2046 | Y3: =Indata!$C$5+21 -> 2047 | Z3: =Indata!$C$5+22 -> 2048 | AA3: =Indata!$C$5+23 -> 2049 | AB3: =Indata!$C$5+24 -> 2050
A4: 'Indata'!A1 | B4: År i kalkyl | D4: 1 | E4: 2 | F4: 3 | G4: 4 | H4: 5 | I4: 6 | J4: 7 | K4: 8 | L4: 9 | M4: 10 | N4: 11 | O4: 12 | P4: 13 | Q4: 14 | R4: 15 | S4: 16 | T4: 17 | U4: 18 | V4: 19 | W4: 20 | X4: 21 | Y4: 22 | Z4: 23 | AA4: 24 | AB4: 25
A5: 'Kassaflöde'!A1 | B5: Inom kalkylperiod | D5: =IF(D4<=Indata!$C$16,1,0) -> 1 | E5: =IF(E4<=Indata!$C$16,1,0) -> 1 | F5: =IF(F4<=Indata!$C$16,1,0) -> 1 | G5: =IF(G4<=Indata!$C$16,1,0) -> 1 | H5: =IF(H4<=Indata!$C$16,1,0) -> 1 | I5: =IF(I4<=Indata!$C$16,1,0) -> 1 | J5: =IF(J4<=Indata!$C$16,1,0) -> 1 | K5: =IF(K4<=Indata!$C$16,1,0) -> 1 | ... AB5: =IF(AB4<=Indata!$C$16,1,0) -> 0
A7: 'Resultat'!A1 | B7: LÅN, RÄNTA, AMORTERING, AVSKRIVNING
A8: 'Grafer'!A1 | B8: Lånebild över kalkylperioden enligt finansieringsantagandena på Indata-fliken. Bokföringsmässig vy: avskrivning enligt linjär K3-metod över avskrivningstiden.
A9: 'Lönsamhetskontroll'!A1
A10: 'Beräkningslogik'!A1 | B10: Upptaget lån (år) | D10: =SUMIFS(Indata!$R$26:$R$30,Indata!$P$26:$P$30,D3)*Indata!$C$64 -> 74000000 | E10: =SUMIFS(Indata!$R$26:$R$30,Indata!$P$26:$P$30,E3)*Indata!$C$64 -> 0 | F10: =SUMIFS(Indata!$R$26:$R$30,Indata!$P$26:$P$30,F3)*Indata!$C$64 -> 0 | G10: =SUMIFS(Indata!$R$26:$R$30,Indata!$P$26:$P$30,G3)*Indata!$C$64 -> 0 | H10: =SUMIFS(Indata!$R$26:$R$30,Indata!$P$26:$P$30,H3)*Indata!$C$64 -> 0 | I10: =SUMIFS(Indata!$R$26:$R$30,Indata!$P$26:$P$30,I3)*Indata!$C$64 -> 0 | J10: =SUMIFS(Indata!$R$26:$R$30,Indata!$P$26:$P$30,J3)*Indata!$C$64 -> 0 | K10: =SUMIFS(Indata!$R$26:$R$30,Indata!$P$26:$P$30,K3)*Indata!$C$64 -> 0 | ... AB10: =SUMIFS(Indata!$R$26:$R$30,Indata!$P$26:$P$30,AB3)*Indata!$C$64 -> 0
A11: 'Dokumentation'!A1 | B11: Ack. upptaget lån | D11: =D10 -> 74000000 | E11: =D11+E10 -> 74000000 | F11: =E11+F10 -> 74000000 | G11: =F11+G10 -> 74000000 | H11: =G11+H10 -> 74000000 | I11: =H11+I10 -> 74000000 | J11: =I11+J10 -> 74000000 | K11: =J11+K10 -> 74000000 | L11: =K11+L10 -> 74000000 | ... AB11: =AA11+AB10 -> 74000000
B12: Amortering | D12: =-D11*Indata!$C$63 -> -1480000 | E12: =-D13*Indata!$C$63 -> -1450400 | F12: =-E13*Indata!$C$63 -> -1421392 | G12: =-F13*Indata!$C$63 -> -1392964.2 | H12: =-G13*Indata!$C$63 -> -1365104.9 | I12: =-H13*Indata!$C$63 -> -1337802.8 | J12: =-I13*Indata!$C$63 -> -1311046.7 | K12: =-J13*Indata!$C$63 -> -1284825.8 | L12: =-K13*Indata!$C$63 -> -1259129.3 | ... AB12: =-AA13*Indata!$C$63 -> -911354.9
B13: Återstående skuld | D13: =D11+D12 -> 72520000 | E13: =D13+E10+E12 -> 71069600 | F13: =E13+F10+F12 -> 69648208 | G13: =F13+G10+G12 -> 68255244 | H13: =G13+H10+H12 -> 66890139 | I13: =H13+I10+I12 -> 65552336 | J13: =I13+J10+J12 -> 64241289 | K13: =J13+K10+K12 -> 62956464 | L13: =K13+L10+L12 -> 61697334 | ... AB13: =AA13+AB10+AB12 -> 44656390
B14: Långsiktig räntenivå | D14: =MIN(Indata!$C$62,Indata!$C$61+(Indata!$C$62-Indata!$C$61)*(D4/10)) -> 0.031 | E14: =MIN(Indata!$C$62,Indata!$C$61+(Indata!$C$62-Indata!$C$61)*(E4/10)) -> 0.032 | F14: =MIN(Indata!$C$62,Indata!$C$61+(Indata!$C$62-Indata!$C$61)*(F4/10)) -> 0.033 | G14: =MIN(Indata!$C$62,Indata!$C$61+(Indata!$C$62-Indata!$C$61)*(G4/10)) -> 0.034 | H14: =MIN(Indata!$C$62,Indata!$C$61+(Indata!$C$62-Indata!$C$61)*(H4/10)) -> 0.035 | I14: =MIN(Indata!$C$62,Indata!$C$61+(Indata!$C$62-Indata!$C$61)*(I4/10)) -> 0.036 | J14: =MIN(Indata!$C$62,Indata!$C$61+(Indata!$C$62-Indata!$C$61)*(J4/10)) -> 0.037 | K14: =MIN(Indata!$C$62,Indata!$C$61+(Indata!$C$62-Indata!$C$61)*(K4/10)) -> 0.038 | ... AB14: =MIN(Indata!$C$62,Indata!$C$61+(Indata!$C$62-Indata!$C$61)*(AB4/10)) -> 0.04
B15: Räntekostnad | D15: =-D13*D14 -> -2248120 | E15: =-E13*E14 -> -2274227.2 | F15: =-F13*F14 -> -2298390.9 | G15: =-G13*G14 -> -2320678.3 | H15: =-H13*H14 -> -2341154.9 | I15: =-I13*I14 -> -2359884.1 | J15: =-J13*J14 -> -2376927.7 | K15: =-K13*K14 -> -2392345.6 | ... AB15: =-AB13*AB14 -> -1786255.6
B17: Eget kapital-insats | D17: =-SUMIFS(Indata!$R$26:$R$30,Indata!$P$26:$P$30,D3)*(1-Indata!$C$64) -> -126000000 | E17: =-SUMIFS(Indata!$R$26:$R$30,Indata!$P$26:$P$30,E3)*(1-Indata!$C$64) -> 0 | F17: =-SUMIFS(Indata!$R$26:$R$30,Indata!$P$26:$P$30,F3)*(1-Indata!$C$64) -> 0 | G17: =-SUMIFS(Indata!$R$26:$R$30,Indata!$P$26:$P$30,G3)*(1-Indata!$C$64) -> 0 | H17: =-SUMIFS(Indata!$R$26:$R$30,Indata!$P$26:$P$30,H3)*(1-Indata!$C$64) -> 0 | I17: =-SUMIFS(Indata!$R$26:$R$30,Indata!$P$26:$P$30,I3)*(1-Indata!$C$64) -> 0 | J17: =-SUMIFS(Indata!$R$26:$R$30,Indata!$P$26:$P$30,J3)*(1-Indata!$C$64) -> 0 | K17: =-SUMIFS(Indata!$R$26:$R$30,Indata!$P$26:$P$30,K3)*(1-Indata!$C$64) -> 0 | ... AB17: =-SUMIFS(Indata!$R$26:$R$30,Indata!$P$26:$P$30,AB3)*(1-Indata!$C$64) -> 0
B18: Avskrivning (per år) | D18: =IF(D5=0,0,-Indata!$C$17/Indata!$C$19) -> -6060606.1 | E18: =IF(E5=0,0,-Indata!$C$17/Indata!$C$19) -> -6060606.1 | F18: =IF(F5=0,0,-Indata!$C$17/Indata!$C$19) -> -6060606.1 | G18: =IF(G5=0,0,-Indata!$C$17/Indata!$C$19) -> -6060606.1 | H18: =IF(H5=0,0,-Indata!$C$17/Indata!$C$19) -> -6060606.1 | I18: =IF(I5=0,0,-Indata!$C$17/Indata!$C$19) -> -6060606.1 | J18: =IF(J5=0,0,-Indata!$C$17/Indata!$C$19) -> -6060606.1 | K18: =IF(K5=0,0,-Indata!$C$17/Indata!$C$19) -> -6060606.1 | ... AB18: =IF(AB5=0,0,-Indata!$C$17/Indata!$C$19) -> 0

Sheet Resultat
B1: LEJONFASTIGHETER · RESULTAT
A2: 'Försättsblad'!A1 | B2: Resultat
A3: 'Översikt'!A1 | B3: Kravhyra och utfall vid bindande hyra
A4: 'Indata'!A1 | B4: KRAVHYRA — PROJEKTETS ÅRSHYRA
A5: 'Kassaflöde'!A1
A6: 'Finansiering'!A1 | B6: Investeringsutfall | C6: Lägsta (−X%) | D6: Mål | E6: Högsta (+X%)
B7: Investering | C7: =Indata!R31*(1-Indata!C68) -> 180000000 | D7: =Indata!R31 -> 200000000 | E7: =Indata!R31*(1+Indata!C68) -> 2.2e+08
A8: 'Grafer'!A1 | B8: Investering per kvm | C8: =IFERROR(C7/Indata!F31,0) -> 36000 | D8: =IFERROR(D7/Indata!F31,0) -> 40000 | E8: =IFERROR(E7/Indata!F31,0) -> 44000
A9: 'Lönsamhetskontroll'!A1
A10: 'Beräkningslogik'!A1 | B10: 1. Kravhyra för NPV ≥ 0 | C10: =-(Beräkningslogik!C119-Indata!C68*Beräkningslogik!C118)/Beräkningslogik!C140 -> 10726244 | D10: =-Beräkningslogik!C119/Beräkningslogik!C140 -> 11631222 | E10: =-(Beräkningslogik!C119+Indata!C68*Beräkningslogik!C118)/Beräkningslogik!C140 -> 12536199
A11: 'Dokumentation'!A1 | B11: 2. Kravhyra för IRR ≥ avkastningskrav | C11: =-(Beräkningslogik!C177+Indata!C68*Indata!R31*(1-Indata!C64))/Beräkningslogik!C193 -> 10507485 | D11: =-Beräkningslogik!C177/Beräkningslogik!C193 -> 11129728 | E11: =-(Beräkningslogik!C177-Indata!C68*Indata!R31*(1-Indata!C64))/Beräkningslogik!C193 -> 11751970
B12: 3. Kravhyra för MV ≥ BV år 20 | C12: =(Beräkningslogik!C204*(1-Indata!C68)-Beräkningslogik!C202)/Beräkningslogik!C203 -> 5426681 | D12: =(Beräkningslogik!C204-Beräkningslogik!C202)/Beräkningslogik!C203 -> 5729582.1 | E12: =(Beräkningslogik!C204*(1+Indata!C68)-Beräkningslogik!C202)/Beräkningslogik!C203 -> 6032483.3
B14: Bindande kravhyra | C14: =MAX(C10,C11,C12) -> 10726244 | D14: =MAX(D10,D11,D12) -> 11631222 | E14: =MAX(E10,E11,E12) -> 12536199 | F14: kr/år
B15: Bindande krav | C15: =IF(C14=C10,"NPV",IF(C14=C11,"IRR","MV")) -> NPV | D15: =IF(D14=D10,"NPV",IF(D14=D11,"IRR","MV")) -> NPV | E15: =IF(E14=E10,"NPV",IF(E14=E11,"IRR","MV")) -> NPV
B16: Genomsnitt kr/m²/år (totalarea) | C16: =IFERROR(C14/Indata!F31,0) -> 2145.2489 | D16: =IFERROR(D14/Indata!F31,0) -> 2326.2443 | E16: =IFERROR(E14/Indata!F31,0) -> 2507.2398
B18: Förklaring | C18: Bindande kravhyra = den lägsta årshyra som uppfyller alla tre lönsamhetskrav samtidigt. NPV, IRR och framtida marknadsvärde kontrolleras var för sig på fliken Lönsamhetskontroll.
B19: Tolkning | C19: Avtalet bör ange hyresspannet ovan (lägsta–högsta utfall). Slutlig hyra fastställs när investeringsutfallet är känt vid projektavslut.
B22: FÖRDELNING PER HUS (VID MÅL-UTFALL)
B24: Objekt | C24: Andel | D24: Årshyra (kr/år) | E24: Hyra kr/m²/år | F24: Tillträde
B25: =IF(Indata!B26="","(ej ifyllt)",Indata!B26) -> Skola | C25: =IFERROR(Indata!R26/Indata!R31,0) -> 1 | D25: =C25*D$14 -> 11631222 | E25: =IFERROR(D25/Indata!F26,0) -> 2326.2443 | F25: =IF(Indata!K26="","",Indata!K26) -> 2026
B26: =IF(Indata!B27="","(ej ifyllt)",Indata!B27) -> (ej ifyllt) | C26: =IFERROR(Indata!R27/Indata!R31,0) -> 0 | D26: =C26*D$14 -> 0 | E26: =IFERROR(D26/Indata!F27,0) -> 0 | F26: =IF(Indata!K27="","",Indata!K27)
B27: =IF(Indata!B28="","(ej ifyllt)",Indata!B28) -> (ej ifyllt) | C27: =IFERROR(Indata!R28/Indata!R31,0) -> 0 | D27: =C27*D$14 -> 0 | E27: =IFERROR(D27/Indata!F28,0) -> 0 | F27: =IF(Indata!K28="","",Indata!K28)
B28: =IF(Indata!B29="","(ej ifyllt)",Indata!B29) -> (ej ifyllt) | C28: =IFERROR(Indata!R29/Indata!R31,0) -> 0 | D28: =C28*D$14 -> 0 | E28: =IFERROR(D28/Indata!F29,0) -> 0 | F28: =IF(Indata!K29="","",Indata!K29)
B29: =IF(Indata!B30="","(ej ifyllt)",Indata!B30) -> (ej ifyllt) | C29: =IFERROR(Indata!R30/Indata!R31,0) -> 0 | D29: =C29*D$14 -> 0 | E29: =IFERROR(D29/Indata!F30,0) -> 0 | F29: =IF(Indata!K30="","",Indata!K30)
B30: Totalt | C30: =SUM(C25:C29) -> 1 | D30: =SUM(D25:D29) -> 11631222
B33: UTFALL VID BINDANDE KRAVHYRA
B34: Vid mål-utfall (bindande kravhyra D14): hur välfodrade är de icke-bindande kraven? Värden < 0 eller IRR < kravet betyder att projektet inte uppfyller kravet vid denna hyra.
B36: NPV (krav 1) | C36: =Lönsamhetskontroll!C9 -> 0 | F36: =Lönsamhetskontroll!D9 -> ✓ Uppfyllt
B37: Faktisk IRR EK (krav 2) | C37: =Lönsamhetskontroll!C45 -> 0.076451715 | D37: Krav | E37: =Indata!C65 -> 0.063 | F37: =Lönsamhetskontroll!D45 -> ✓ Uppfyllt
B38: Marginal IRR mot krav | C38: =Lönsamhetskontroll!C47*100 -> 1.3451715
B39: Marknadsvärde år 20 (krav 3) | C39: =Lönsamhetskontroll!C29 -> 2.3586973e+08 | D39: BV år 20 | E39: =Lönsamhetskontroll!C27 -> 80000000
B40: Differens MV − BV | C40: =Lönsamhetskontroll!C30 -> 1.5586973e+08 | F40: =Lönsamhetskontroll!D30 -> ✓ Uppfyllt

Sheet Grafer
A2: 'Försättsblad'!A1 | B2: LEJONFASTIGHETER · GRAFER
A3: 'Översikt'!A1 | B3: Grafer
A4: 'Indata'!A1 | B4: Kalkylens utveckling i bilder — vid bindande kravhyra och mål-utfall
A5: 'Kassaflöde'!A1
A6: 'Finansiering'!A1
A7: 'Resultat'!A1
A9: 'Lönsamhetskontroll'!A1
A10: 'Beräkningslogik'!A1
A11: 'Dokumentation'!A1
B41: DIAGRAMDATA — UNDERLAG
B42: Refererar Kassaflöde, Indata och Resultat. Diagrammen ovan läser dessa rader.
B44: Kalenderår | C44: =Kassaflöde!D3 -> 2026 | D44: =Kassaflöde!E3 -> 2027 | E44: =Kassaflöde!F3 -> 2028 | F44: =Kassaflöde!G3 -> 2029 | G44: =Kassaflöde!H3 -> 2030 | H44: =Kassaflöde!I3 -> 2031 | I44: =Kassaflöde!J3 -> 2032 | J44: =Kassaflöde!K3 -> 2033 | ... V44: =Kassaflöde!W3 -> 2045
B45: Driftnetto (Mkr) | C45: =Kassaflöde!D23 -> 9231221.7 | D45: =Kassaflöde!E23 -> 9346058.8 | E45: =Kassaflöde!F23 -> 9462215.6 | F45: =Kassaflöde!G23 -> 9579704.9 | G45: =Kassaflöde!H23 -> 9698539.4 | H45: =Kassaflöde!I23 -> 9818731.9 | I45: =Kassaflöde!J23 -> 9940295.4 | J45: =Kassaflöde!K23 -> 10063243 | ... V45: =Kassaflöde!W23 -> 11651346
B46: Ackumulerat driftnetto (Mkr) | C46: =C45 -> 9231221.7 | D46: =D45+C46 -> 18577281 | E46: =E45+D46 -> 28039496 | F46: =F45+E46 -> 37619201 | G46: =G45+F46 -> 47317740 | H46: =H45+G46 -> 57136472 | I46: =I45+H46 -> 67076768 | J46: =J45+I46 -> 77140011 | K46: =K45+J46 -> 87327598 | ... V46: =V45+U46 -> 2.0801049e+08
B47: Total investering (Mkr) | C47: =Indata!$R$31 -> 200000000 | D47: =Indata!$R$31 -> 200000000 | E47: =Indata!$R$31 -> 200000000 | F47: =Indata!$R$31 -> 200000000 | G47: =Indata!$R$31 -> 200000000 | H47: =Indata!$R$31 -> 200000000 | I47: =Indata!$R$31 -> 200000000 | J47: =Indata!$R$31 -> 200000000 | ... V47: =Indata!$R$31 -> 200000000
B49: Hyresspann (kr/år)
C50: ="Lägsta (−"&Indata!C68*100&" %)" -> Lägsta (−10 %) | D50: Mål (bindande) | E50: ="Högsta (+"&Indata!C68*100&" %)" -> Högsta (+10 %)
C51: =Resultat!C14 -> 10726244 | D51: =Resultat!D14 -> 11631222 | E51: =Resultat!E14 -> 12536199

Sheet Lönsamhetskontroll
B1: LEJONFASTIGHETER · LÖNSAMHETSKONTROLL
A2: 'Försättsblad'!A1 | B2: Lönsamhetskontroll
A3: 'Översikt'!A1 | B3: Tre lönsamhetskrav och faktisk IRR
A4: 'Indata'!A1 | B4: 1. NPV ≥ 0 (vid kalkylränta driftnetto)
A5: 'Kassaflöde'!A1
A6: 'Finansiering'!A1 | B6: Kalkylränta driftnetto | C6: =Indata!C7 -> 0.04
A7: 'Resultat'!A1 | B7: Kravhyra NPV (mål) | C7: =Resultat!D10 -> 11631222
A8: 'Grafer'!A1 | B8: NPV vid kravhyra NPV | C8: =Beräkningslogik!C119+Beräkningslogik!C140*Resultat!D10 -> 0 | E8: (ska vara ≈ 0)
B9: NPV vid bindande kravhyra | C9: =Beräkningslogik!C119+Beräkningslogik!C140*Resultat!D14 -> 0 | D9: =IF(C9>=0,"✓ Uppfyllt","✗ Ej uppfyllt") -> ✓ Uppfyllt
A10: 'Beräkningslogik'!A1
A11: 'Dokumentation'!A1
B12: 2. IRR eget kapital ≥ avkastningskrav
B14: Avkastningskrav eget kapital | C14: =Indata!C65 -> 0.063
B15: Belåningsgrad | C15: =Indata!C64 -> 0.37
B16: Kravhyra IRR (mål) | C16: =Resultat!D11 -> 11129728
B17: NPV EK vid avk.krav, vid kravhyra IRR | C17: =Beräkningslogik!C177+Beräkningslogik!C193*Resultat!D11 -> 0 | E17: (ska vara ≈ 0)
B18: NPV EK vid bindande kravhyra | C18: =Beräkningslogik!C177+Beräkningslogik!C193*Resultat!D14 -> 10154924 | D18: =IF(C18>=0,"✓ Uppfyllt","✗ Ej uppfyllt") -> ✓ Uppfyllt
B21: 3. Marknadsvärde år 20 ≥ bokfört värde år 20
B23: Kalkylperiod (år 20) | C23: =Indata!C16 -> 20
B24: Direktavkastning | C24: =Indata!$D$81 -> 0.05
B25: Byggnadsvärde (dag 1) | C25: =Indata!C17 -> 200000000
B26: Avskrivningstakt | C26: =Indata!C18 -> 0.03
B27: Bokfört värde år 20 | C27: =Beräkningslogik!C204 -> 80000000 | E27: Formel: (byggnadsv + bef BV + projbel) × (1 - N × avskr%)
B28: Driftnetto år 21 vid bindande kravhyra | C28: =Beräkningslogik!C199+Beräkningslogik!C201*Resultat!D14 -> 11793486
B29: Marknadsvärde år 20 (Gordon) | C29: =C28/C24 -> 2.3586973e+08 | E29: Formel: driftnetto år 21 / direktavkastning
B30: Differens (MV - BV) | C30: =C29-C27 -> 1.5586973e+08 | D30: =IF(C30>=0,"✓ Uppfyllt","✗ Nedskrivningsrisk") -> ✓ Uppfyllt
B42: FAKTISK IRR (vid bindande kravhyra)
B43: EK-cashflow vid bindande kravhyra | F43: =Beräkningslogik!D173+(Beräkningslogik!D188-Beräkningslogik!D173)*Resultat!$D$14/1000000 -> -1.204969e+08 | G43: =Beräkningslogik!E173+(Beräkningslogik!E188-Beräkningslogik!E173)*Resultat!$D$14/1000000 -> 5621431.6 | H43: =Beräkningslogik!F173+(Beräkningslogik!F188-Beräkningslogik!F173)*Resultat!$D$14/1000000 -> 5742432.8 | I43: =Beräkningslogik!G173+(Beräkningslogik!G188-Beräkningslogik!G173)*Resultat!$D$14/1000000 -> 5866062.5 | J43: =Beräkningslogik!H173+(Beräkningslogik!H188-Beräkningslogik!H173)*Resultat!$D$14/1000000 -> 5992279.6 | K43: =Beräkningslogik!I173+(Beräkningslogik!I188-Beräkningslogik!I173)*Resultat!$D$14/1000000 -> 6121045 | L43: =Beräkningslogik!J173+(Beräkningslogik!J188-Beräkningslogik!J173)*Resultat!$D$14/1000000 -> 6252321 | M43: =Beräkningslogik!K173+(Beräkningslogik!K188-Beräkningslogik!K173)*Resultat!$D$14/1000000 -> 6386071.4 | ... AD43: =Beräkningslogik!AB173+(Beräkningslogik!AB188-Beräkningslogik!AB173)*Resultat!$D$14/1000000 -> 9680279.1
B45: Faktisk IRR EK | C45: =IFERROR(IRR(F43:AD43),"Ej beräkningsbar") -> 0.076451715 | D45: =IF(ISNUMBER(C45),IF(C45>=C46,"✓ Uppfyllt","✗ Ej uppfyllt"),"") -> ✓ Uppfyllt
B46: Avkastningskrav | C46: =Indata!C65 -> 0.063
B47: Marginal mot krav | C47: =IFERROR(C45-C46,"") -> 0.013451715
B50: KÄNSLIGHETSANALYS — MARKNADSVÄRDE VID EXIT
B51: Hur sårbart är projektet om marknadsvärdet vid år 20 visar sig avvika från bedömningen? Bas-bedömningen är driftnetto år 21 / direktavkastning.
B53: Scenario | C53: Marknadsvärde | D53: Diff mot BV | E53: IRR EK | F53: Status
B54: −40 % | C54: =$C$29*(1+-0.4) -> 1.4152184e+08 | D54: =C54-$C$27 -> 61521837 | E54: =IFERROR(IRR(F64:AD64),"") -> 0.063801866 | F54: =IF(ISNUMBER(E54),IF(E54>=Indata!$C$65,"✓","⚠ IRR<krav"),"") -> ✓
B55: −30 % | C55: =$C$29*(1+-0.3) -> 1.6510881e+08 | D55: =C55-$C$27 -> 85108810 | E55: =IFERROR(IRR(F65:AD65),"") -> 0.067427322 | F55: =IF(ISNUMBER(E55),IF(E55>=Indata!$C$65,"✓","⚠ IRR<krav"),"") -> ✓
B56: −20 % | C56: =$C$29*(1+-0.2) -> 1.8869578e+08 | D56: =C56-$C$27 -> 1.0869578e+08 | E56: =IFERROR(IRR(F66:AD66),"") -> 0.070702272 | F56: =IF(ISNUMBER(E56),IF(E56>=Indata!$C$65,"✓","⚠ IRR<krav"),"") -> ✓
B57: −10 % | C57: =$C$29*(1+-0.1) -> 2.1228276e+08 | D57: =C57-$C$27 -> 1.3228276e+08 | E57: =IFERROR(IRR(F67:AD67),"") -> 0.073694067 | F57: =IF(ISNUMBER(E57),IF(E57>=Indata!$C$65,"✓","⚠ IRR<krav"),"") -> ✓
B58: Bas | C58: =$C$29*(1+0) -> 2.3586973e+08 | D58: =C58-$C$27 -> 1.5586973e+08 | E58: =IFERROR(IRR(F68:AD68),"") -> 0.076451715 | F58: =IF(ISNUMBER(E58),IF(E58>=Indata!$C$65,"✓","⚠ IRR<krav"),"") -> ✓
B59: +10 % | C59: =$C$29*(1+0.1) -> 2.594567e+08 | D59: =C59-$C$27 -> 1.794567e+08 | E59: =IFERROR(IRR(F69:AD69),"") -> 0.079012102 | F59: =IF(ISNUMBER(E59),IF(E59>=Indata!$C$65,"✓","⚠ IRR<krav"),"") -> ✓
...

Sheet Beräkningslogik
B1: LEJONFASTIGHETER · BERÄKNINGSLOGIK
A2: 'Försättsblad'!A1 | B2: Beräkningslogik
A3: 'Översikt'!A1 | B3: Så fungerar mallens kärnberäkning
A4: 'Indata'!A1
A5: 'Kassaflöde'!A1
A6: 'Finansiering'!A1 | B6: STEG 1 — Räkna NPV vid två testhyror (0 kr och 1 Mkr/år)
A7: 'Resultat'!A1 | B7: NPV vid årshyra = 0 kr | C7: =Beräkningslogik!C119 -> -257050000 | D7: (rad 119 — NPV vid 0 hyra)
A8: 'Grafer'!A1 | B8: NPV vid årshyra = 1 000 000 kr | C8: =Beräkningslogik!C139 -> -234950000 | D8: (rad 139 — NPV vid 1 Mkr)
A9: 'Lönsamhetskontroll'!A1
B10: STEG 2 — Härled hur mycket NPV ändras per krona hyra (lutningen b)
A11: 'Dokumentation'!A1 | B11: Skillnad i NPV | C11: =C8-C7 -> 22100000 | D11: (per 1 Mkr hyra)
B12: Känslighet b (per kr hyra) | C12: =C11/1000000 -> 22.1 | D12: (rad 140 — b_NPV)
B14: STEG 3 — Lös linjärt: kravhyran är där NPV korsar noll, dvs −NPV(0) / b
B15: Modell: NPV = NPV_0 + b × hyra
B16: Sätter NPV = 0 → hyra = −NPV_0 / b
B18: Kravhyra NPV (mål) | C18: =-C7/C12 -> 11631222 | D18: dvs −NPV₀ / b
B20: Kontroll mot Resultat | C20: =Resultat!D10 -> 11631222 | D20: (ska vara samma som C18)
B23: SAMMA PRINCIP FÖR ALLA TRE LÖNSAMHETSKRAVEN
B25: Krav | C25: Beräknad kravhyra | D25: Block nedan på denna flik
B26: 1. NPV ≥ 0 | C26: =Resultat!D10 -> 11631222 | D26: Block A (rad 59–119) + Block B (rad 121–140)
B27: 2. IRR EK ≥ avkastningskrav | C27: =Resultat!D11 -> 11129728 | D27: Block D (rad 164–177) + Block E (rad 179–195)
B28: 3. MV ≥ BV år 20 | C28: =Resultat!D12 -> 5729582.1 | D28: Block F (rad 197–204)
B30: Bindande kravhyra | C30: =MAX(C26,C27,C28) -> 11631222 | D30: dvs max av de tre
B33: VARFÖR METODEN ÄR EKVIVALENT MED ITERATIV MÅLSÖKNING
B35: Iterativ målsökning (Excel Goal Seek) startar med en gissning, räknar NPV, justerar gissningen, räknar igen, och fortsätter tills NPV är tillräckligt nära noll. Det är långsamt och fungerar inte automatiskt vid scenarier.
B37: Den linjära metoden använder samma underliggande matematik men löser ekvationen i ett enda steg. Eftersom NPV(hyra) = NPV_0 + b × hyra är en rät linje räcker det med två punkter för att hitta var den korsar noll. Resultatet är exakt — inte en approximation.
B40: Fördelar:
B41: • En enda omberäkning räcker — ingen iteration
B42: • Tre scenarier (låg/mål/hög) räknas automatiskt
B43: • Tre lönsamhetskrav räknas parallellt med samma metod
B44: • Resultaten är exakta, inte avrundade approximationer
B46: TEKNISKA BERÄKNINGSBLOCK — BELOPP I TKR
B47: Rådata bakom kravhyrorna. Block A/B ger NPV-kravet, D/E ger IRR-kravet, F ger MV-kravet. Belopp i tkr.
B52: Kalenderår | D52: =Indata!$C$5+0 -> 2026 | E52: =Indata!$C$5+1 -> 2027 | F52: =Indata!$C$5+2 -> 2028 | G52: =Indata!$C$5+3 -> 2029 | H52: =Indata!$C$5+4 -> 2030 | I52: =Indata!$C$5+5 -> 2031 | J52: =Indata!$C$5+6 -> 2032 | K52: =Indata!$C$5+7 -> 2033 | L52: =Indata!$C$5+8 -> 2034 | M52: =Indata!$C$5+9 -> 2035 | N52: =Indata!$C$5+10 -> 2036 | O52: =Indata!$C$5+11 -> 2037 | P52: =Indata!$C$5+12 -> 2038 | Q52: =Indata!$C$5+13 -> 2039 | R52: =Indata!$C$5+14 -> 2040 | S52: =Indata!$C$5+15 -> 2041 | T52: =Indata!$C$5+16 -> 2042 | U52: =Indata!$C$5+17 -> 2043 | V52: =Indata!$C$5+18 -> 2044 | W52: =Indata!$C$5+19 -> 2045 | X52: =Indata!$C$5+20 -> 2046 | Y52: =Indata!$C$5+21 -> 2047 | Z52: =Indata!$C$5+22 -> 2048 | AA52: =Indata!$C$5+23 -> 2049 | AB52: =Indata!$C$5+24 -> 2050
B53: År i kalkyl | D53: 1 | E53: 2 | F53: 3 | G53: 4 | H53: 5 | I53: 6 | J53: 7 | K53: 8 | L53: 9 | M53: 10 | N53: 11 | O53: 12 | P53: 13 | Q53: 14 | R53: 15 | S53: 16 | T53: 17 | U53: 18 | V53: 19 | W53: 20 | X53: 21 | Y53: 22 | Z53: 23 | AA53: 24 | AB53: 25
B54: Inom kalkylperiod | D54: =IF(D53<=Indata!$C$16,1,0) -> 1 | E54: =IF(E53<=Indata!$C$16,1,0) -> 1 | F54: =IF(F53<=Indata!$C$16,1,0) -> 1 | G54: =IF(G53<=Indata!$C$16,1,0) -> 1 | H54: =IF(H53<=Indata!$C$16,1,0) -> 1 | I54: =IF(I53<=Indata!$C$16,1,0) -> 1 | J54: =IF(J53<=Indata!$C$16,1,0) -> 1 | K54: =IF(K53<=Indata!$C$16,1,0) -> 1 | ... AB54: =IF(AB53<=Indata!$C$16,1,0) -> 0
B55: Area Nyb (aktiv) | D55: =SUMIFS(Indata!$E$26:$E$79,Indata!$C$26:$C$79,"Nyb",Indata!$P$26:$P$79,"<="&D52)+SUMIFS(Indata!$E$26:$E$79,Indata!$C$26:$C$79,"Omb",Indata!$P$26:$P$79,"<="&D52)+SUMIFS(Indata!$E$26:$E$79,Indata!$C$26:$C$79,"Ins",Indata!$P$26:$P$79,"<="&D52) -> 5000 | E55: =SUMIFS(Indata!$E$26:$E$79,Indata!$C$26:$C$79,"Nyb",Indata!$P$26:$P$79,"<="&E52)+SUMIFS(Indata!$E$26:$E$79,Indata!$C$26:$C$79,"Omb",Indata!$P$26:$P$79,"<="&E52)+SUMIFS(Indata!$E$26:$E$79,Indata!$C$26:$C$79,"Ins",Indata!$P$26:$P$79,"<="&E52) -> 5000 | F55: =SUMIFS(Indata!$E$26:$E$79,Indata!$C$26:$C$79,"Nyb",Indata!$P$26:$P$79,"<="&F52)+SUMIFS(Indata!$E$26:$E$79,Indata!$C$26:$C$79,"Omb",Indata!$P$26:$P$79,"<="&F52)+SUMIFS(Indata!$E$26:$E$79,Indata!$C$26:$C$79,"Ins",Indata!$P$26:$P$79,"<="&F52) -> 5000 | G55: =SUMIFS(Indata!$E$26:$E$79,Indata!$C$26:$C$79,"Nyb",Indata!$P$26:$P$79,"<="&G52)+SUMIFS(Indata!$E$26:$E$79,Indata!$C$26:$C$79,"Omb",Indata!$P$26:$P$79,"<="&G52)+SUMIFS(Indata!$E$26:$E$79,Indata!$C$26:$C$79,"Ins",Indata!$P$26:$P$79,"<="&G52) -> 5000 | H55: =SUMIFS(Indata!$E$26:$E$79,Indata!$C$26:$C$79,"Nyb",Indata!$P$26:$P$79,"<="&H52)+SUMIFS(Indata!$E$26:$E$79,Indata!$C$26:$C$79,"Omb",Indata!$P$26:$P$79,"<="&H52)+SUMIFS(Indata!$E$26:$E$79,Indata!$C$26:$C$79,"Ins",Indata!$P$26:$P$79,"<="&H52) -> 5000 | I55: =SUMIFS(Indata!$E$26:$E$79,Indata!$C$26:$C$79,"Nyb",Indata!$P$26:$P$79,"<="&I52)+SUMIFS(Indata!$E$26:$E$79,Indata!$C$26:$C$79,"Omb",Indata!$P$26:$P$79,"<="&I52)+SUMIFS(Indata!$E$26:$E$79,Indata!$C$26:$C$79,"Ins",Indata!$P$26:$P$79,"<="&I52) -> 5000 | J55: =SUMIFS(Indata!$E$26:$E$79,Indata!$C$26:$C$79,"Nyb",Indata!$P$26:$P$79,"<="&J52)+SUMIFS(Indata!$E$26:$E$79,Indata!$C$26:$C$79,"Omb",Indata!$P$26:$P$79,"<="&J52)+SUMIFS(Indata!$E$26:$E$79,Indata!$C$26:$C$79,"Ins",Indata!$P$26:$P$79,"<="&J52) -> 5000 | K55: =SUMIFS(Indata!$E$26:$E$79,Indata!$C$26:$C$79,"Nyb",Indata!$P$26:$P$79,"<="&K52)+SUMIFS(Indata!$E$26:$E$79,Indata!$C$26:$C$79,"Omb",Indata!$P$26:$P$79,"<="&K52)+SUMIFS(Indata!$E$26:$E$79,Indata!$C$26:$C$79,"Ins",Indata!$P$26:$P$79,"<="&K52) -> 5000 | ... AB55: =SUMIFS(Indata!$E$26:$E$79,Indata!$C$26:$C$79,"Nyb",Indata!$P$26:$P$79,"<="&AB52)+SUMIFS(Indata!$E$26:$E$79,Indata!$C$26:$C$79,"Omb",Indata!$P$26:$P$79,"<="&AB52)+SUMIFS(Indata!$E$26:$E$79,Indata!$C$26:$C$79,"Ins",Indata!$P$26:$P$79,"<="&AB52) -> 5000
B56: Area Bef (aktiv) | D56: =SUMIFS(Indata!$D$26:$D$79,Indata!$C$26:$C$79,"Bef",Indata!$P$26:$P$79,"<="&D52)+SUMIFS(Indata!$D$26:$D$79,Indata!$C$26:$C$79,"Omb",Indata!$P$26:$P$79,"<="&D52)+SUMIFS(Indata!$D$26:$D$79,Indata!$C$26:$C$79,"Nyb",Indata!$P$26:$P$79,"<="&D52)+SUMIFS(Indata!$D$26:$D$79,Indata!$C$26:$C$79,"Ins",Indata!$P$26:$P$79,"<="&D52) -> 0 | E56: =SUMIFS(Indata!$D$26:$D$79,Indata!$C$26:$C$79,"Bef",Indata!$P$26:$P$79,"<="&E52)+SUMIFS(Indata!$D$26:$D$79,Indata!$C$26:$C$79,"Omb",Indata!$P$26:$P$79,"<="&E52)+SUMIFS(Indata!$D$26:$D$79,Indata!$C$26:$C$79,"Nyb",Indata!$P$26:$P$79,"<="&E52)+SUMIFS(Indata!$D$26:$D$79,Indata!$C$26:$C$79,"Ins",Indata!$P$26:$P$79,"<="&E52) -> 0 | F56: =SUMIFS(Indata!$D$26:$D$79,Indata!$C$26:$C$79,"Bef",Indata!$P$26:$P$79,"<="&F52)+SUMIFS(Indata!$D$26:$D$79,Indata!$C$26:$C$79,"Omb",Indata!$P$26:$P$79,"<="&F52)+SUMIFS(Indata!$D$26:$D$79,Indata!$C$26:$C$79,"Nyb",Indata!$P$26:$P$79,"<="&F52)+SUMIFS(Indata!$D$26:$D$79,Indata!$C$26:$C$79,"Ins",Indata!$P$26:$P$79,"<="&F52) -> 0 | G56: =SUMIFS(Indata!$D$26:$D$79,Indata!$C$26:$C$79,"Bef",Indata!$P$26:$P$79,"<="&G52)+SUMIFS(Indata!$D$26:$D$79,Indata!$C$26:$C$79,"Omb",Indata!$P$26:$P$79,"<="&G52)+SUMIFS(Indata!$D$26:$D$79,Indata!$C$26:$C$79,"Nyb",Indata!$P$26:$P$79,"<="&G52)+SUMIFS(Indata!$D$26:$D$79,Indata!$C$26:$C$79,"Ins",Indata!$P$26:$P$79,"<="&G52) -> 0 | H56: =SUMIFS(Indata!$D$26:$D$79,Indata!$C$26:$C$79,"Bef",Indata!$P$26:$P$79,"<="&H52)+SUMIFS(Indata!$D$26:$D$79,Indata!$C$26:$C$79,"Omb",Indata!$P$26:$P$79,"<="&H52)+SUMIFS(Indata!$D$26:$D$79,Indata!$C$26:$C$79,"Nyb",Indata!$P$26:$P$79,"<="&H52)+SUMIFS(Indata!$D$26:$D$79,Indata!$C$26:$C$79,"Ins",Indata!$P$26:$P$79,"<="&H52) -> 0 | I56: =SUMIFS(Indata!$D$26:$D$79,Indata!$C$26:$C$79,"Bef",Indata!$P$26:$P$79,"<="&I52)+SUMIFS(Indata!$D$26:$D$79,Indata!$C$26:$C$79,"Omb",Indata!$P$26:$P$79,"<="&I52)+SUMIFS(Indata!$D$26:$D$79,Indata!$C$26:$C$79,"Nyb",Indata!$P$26:$P$79,"<="&I52)+SUMIFS(Indata!$D$26:$D$79,Indata!$C$26:$C$79,"Ins",Indata!$P$26:$P$79,"<="&I52) -> 0 | J56: =SUMIFS(Indata!$D$26:$D$79,Indata!$C$26:$C$79,"Bef",Indata!$P$26:$P$79,"<="&J52)+SUMIFS(Indata!$D$26:$D$79,Indata!$C$26:$C$79,"Omb",Indata!$P$26:$P$79,"<="&J52)+SUMIFS(Indata!$D$26:$D$79,Indata!$C$26:$C$79,"Nyb",Indata!$P$26:$P$79,"<="&J52)+SUMIFS(Indata!$D$26:$D$79,Indata!$C$26:$C$79,"Ins",Indata!$P$26:$P$79,"<="&J52) -> 0 | K56: =SUMIFS(Indata!$D$26:$D$79,Indata!$C$26:$C$79,"Bef",Indata!$P$26:$P$79,"<="&K52)+SUMIFS(Indata!$D$26:$D$79,Indata!$C$26:$C$79,"Omb",Indata!$P$26:$P$79,"<="&K52)+SUMIFS(Indata!$D$26:$D$79,Indata!$C$26:$C$79,"Nyb",Indata!$P$26:$P$79,"<="&K52)+SUMIFS(Indata!$D$26:$D$79,Indata!$C$26:$C$79,"Ins",Indata!$P$26:$P$79,"<="&K52) -> 0 | ... AB56: =SUMIFS(Indata!$D$26:$D$79,Indata!$C$26:$C$79,"Bef",Indata!$P$26:$P$79,"<="&AB52)+SUMIFS(Indata!$D$26:$D$79,Indata!$C$26:$C$79,"Omb",Indata!$P$26:$P$79,"<="&AB52)+SUMIFS(Indata!$D$26:$D$79,Indata!$C$26:$C$79,"Nyb",Indata!$P$26:$P$79,"<="&AB52)+SUMIFS(Indata!$D$26:$D$79,Indata!$C$26:$C$79,"Ins",Indata!$P$26:$P$79,"<="&AB52) -> 0
B57: Total area | D57: =D55+D56 -> 5000 | E57: =E55+E56 -> 5000 | F57: =F55+F56 -> 5000 | G57: =G55+G56 -> 5000 | H57: =H55+H56 -> 5000 | I57: =I55+I56 -> 5000 | J57: =J55+J56 -> 5000 | K57: =K55+K56 -> 5000 | ... AB57: =AB55+AB56 -> 5000
B59: BLOCK A — Bas-kassaflöde vid årshyra = 0 · tkr
...

Sheet Dokumentation
B1: LEJONFASTIGHETER · DOKUMENTATION
A2: 'Försättsblad'!A1 | B2: Dokumentation
A3: 'Översikt'!A1 | B3: Antaganden, formler och versionsanteckningar
A4: 'Indata'!A1 | B4: 1. Syfte
A5: 'Kassaflöde'!A1 | B5: Mallen beräknar lönsamhetsgränsen (kravhyran) för investeringar i Lejonfastigheters fastigheter. Kravhyran är den lägsta årshyra som uppfyller alla tre lönsamhetskrav samtidigt. Hyresspannet (±10% på investeringen) blir ett intervall som skrivs in i avtalet.
A6: 'Finansiering'!A1
A7: 'Resultat'!A1 | B7: 2. Grundprincip: en kalkyl = en hyresgäst = en verksamhet
A8: 'Grafer'!A1 | B8: Mallen är byggd för EN hyresgäst och EN verksamhetstyp per fil. Vid projekt med flera hyresgäster (t.ex. vårdboende + förskola i samma hus) ska en separat kalkyl göras per hyresgäst. Gemensamma investeringar fördelas manuellt enligt BRA eller BTA innan beloppen matas in i respektive kalkyl.
A9: 'Lönsamhetskontroll'!A1
A10: 'Beräkningslogik'!A1 | B10: 3. Tre lönsamhetskrav
B12: Kravhyran beräknas så att alla tre följande krav uppfylls simultant:
B14: KRAV 1 — NPV ≥ 0
B15: Projektets nuvärde över kalkylperioden, diskonterat till kalkylräntan för driftnetto (Indata C7), ska vara minst 0.
B16: Formel: NPV = Σ(driftnetto/(1+kalkylränta)^år) + PV restvärde + PV investering
B17: Rad på Kassaflöde: C70 (NPV vid 0 hyra), C91 (känslighet), Resultat D10 (kravhyra NPV)
B19: KRAV 2 — IRR eget kapital ≥ avkastningskrav
B20: Internräntan på eget kapital-kassaflödet ska vara minst avkastningskravet (Indata C65, default 6,3%). Eget kapital-kassaflödet beräknas med 37% belåning (default) och inkluderar räntekostnad, amortering, skatt, EK-insats och exit-värde.
B22: Exit-värde = marknadsvärde − återstående skuld
B23: Marknadsvärde = driftnetto år 21 / direktavkastning (Gordon-modellen)
B25: Den tidigare 0,4/0,6-viktningen från LM 371 är borttagen. Se sektion 14 för det fullständiga resonemanget.
B26: Rad på Kassaflöde: C128 (NPV EK vid 0 hyra), C144 (b_IRR), Resultat D11 (kravhyra IRR)
B28: KRAV 3 — Marknadsvärde år 20 ≥ bokfört värde år 20
... B169: Reinvesteringsbehov hanteras explicit via Indata sektion 5 (re-investering / hyresatt UH), där användaren matar in faktiskt förväntat behov. Detta är den ekonomiskt korrekta platsen att hantera skick-relaterade kostnader.
